Workbook

Sheet INTRO

Sheet START
B2: INPUT cells
B3: COMPANY SET-UP | Day 1, YEAR 1
B5: Nr of Shares | C5: Allocation of Shares | F5: Notes
B6: 1000 | C6: =B6/B8 -> 0.66666667 | D6: Owner | F6: For the name & idea
B7: 500 | C7: =B7/B8 -> 0.33333333 | D7: Investor | F7: Bill needs money:
B8: =SUM(B6:B7) -> 1500 | C8: TOT | F8: he sells 1/3 of the company (500 shares) to raise money
B10: Share value
B11: Per Share | C11: 1
B13: Business Worth (Equity)
B14: 1000 | D14: Owner | F14: Idea-Goodwill, 1$/share
B15: 500 | D15: Investor | F15: Equity Issued, 1$/share
B16: =SUM(B14:B15) -> 1500 | C16: TOT | F16: <--- NOW the business is worth
B19: Borrowed Money
B20: Debt | C20: Annual Interest Rate | D20: Annual Interest | F20: Bill need more money. He decides to borrow it
B21: 250 | C21: 0.1 | D21: =C21*B21 -> 25 | F21: The lender provides $250 at 10% interest rate
F22: Bill decides to borrow instead of selling other shares, to control the business and keep future profits (in case the business in succesful)
B24: Total Cash
B25: 0 | D25: Owner
B26: =B7 -> 500 | C26: Raised money | D26: Investor | F26: 1$/share
B27: =B21 -> 250 | C27: Raised money | D27: Lender | F27: 10% annual interests
B28: =SUM(B25:B27) -> 750 | C28: TOT

Sheet BS, Y1 DAY 1
B1: BALANCE SHEET | Day 1, YEAR 1
B3: ASSETS | C3: amount
B4: Cash | C4: =START!B28 -> 750 | H4: $750 = $500 from selling 1/3 of the business (500 shares) +$250 of debt
B5: Fixed assets | C5: 0
B6: Inventory | C6: 0
B7: Goodwill | C7: =START!B14 -> 1000 | H7: Goodwill is an intangible asset of a Company.
B8: Total Assets | C8: =SUM(C4:C7) -> 1750 | H8: It comes under different forms: brand, reputation, intellectual property, etc.
H9: It is challenging to value Goodwill. It this case, it is a "given."
B12: LIABILITIES | C12: amount
B13: Debt | C13: =START!B21 -> 250
B14: Total Liability | C14: =C13 -> 250
B17: Shareholders Equity | C17: =START!B16 -> 1500 | H17: Net Worth - Shareholder equity
B18: Per Share | C18: 1
B21: SUMMARY
B22: A | C22: =C8 -> 1750 | E22: L | F22: =C14 -> 250 | H22: =F22/F24 -> 0.14285714 | I22: Low Debt over Total Assets
E23: E | F23: =C17 -> 1500 | H23: =F22/F23 -> 0.16666667 | I23: Low Debt over Equity
B24: TOT A | C24: =C22 -> 1750 | E24: TOT L+E | F24: =F22+F23 -> 1750

Sheet BS, Y! DAY 2
B1: INPUT cells
A3: A) | B3: PROCUREMENTS | DAY 2, YEAR 1 | F3: B) | G3: OPERATIONS (assumpions)
B5: Original cash availability | C5: ='BS, Y1 DAY 1'!C4 -> 750 | G5: Target Annual production of lemonade | H5: 50 | I5: Gallons
G6: Equal to Nr cups | H6: 800 | I6: Cups
B7: NEW ASSETS BREAKDOWN | C7: Amount | E7: Notes
B8: Cash | C8: 250
B9: Fixed assets | C9: 300 | E9: Buy Lemonade stand
B10: Inventory | C10: 200 | E10: Sugar, water, lemon, cups, etc.
B11: TOT | C11: =SUM(C8:C10) -> 750
A13: C) | B13: CASH Spent
B14: Purchase of Fixed Asset & Inventory | C14: =C9+C10 -> 500
A17: D) | B17: BALANCE SHEET | DAY 2, YEAR 1
B19: ASSETS | C19: amount
B20: Cash | C20: =C8 -> 250 | D20: ---> | E20: used money to but assets & inventory
B21: Fixed assets | C21: =C9 -> 300 | D21: <----
B22: Inventory | C22: =C10 -> 200 | D22: <----
B23: Goodwill | C23: ='BS, Y1 DAY 1'!C7 -> 1000
B24: Total Assets | C24: =SUM(C20:C23) -> 1750
B27: LIABILITIES | C27: amount
B28: Debt | C28: ='BS, Y1 DAY 1'!C13 -> 250
B29: Total Liability | C29: =C28 -> 250
B31: Shareholders Equity | C31: ='BS, Y1 DAY 1'!C17 -> 1500
B32: Per Share | C32: 1
B34: SUMMARY
B35: A | C35: =C24 -> 1750 | E35: L | F35: =C29 -> 250
E36: E | F36: =C31 -> 1500
B37: TOT A | C37: =C35 -> 1750 | E37: TOT L+E | F37: =SUM(F35:F36) -> 1750

Sheet IS, end Y1
B2: ASSUPTIONS / PROJECTIONS (Annual)
B5: SALES | C5: Nr | D5: Price | E5: Revenues
B6: cups | C6: 800 | D6: 1 | E6: =C6*D6 -> 800
B8: COSTS | C8: Amount
B9: Staff | C9: 530
B13: INCOME STATEMENT | G13: Notes
B15: Nr. Lemonade Stands | C15: 1
B16: Cups sold (per stand) | C16: 800
B17: Cups sold | C17: =C16*C15 -> 800
B19: Price per cup | C19: =D6 -> 1
B20: Revenues | C20: =C19*C17 -> 800
A22: Less | B22: Cost of Goods Sold (COGS) | C22: =-('BS, Y! DAY 2'!C10) -> -200 | D22: Years | G22: Inventory (V.C.)
A23: Less | B23: Depreciation | C23: =-('BS, Y! DAY 2'!C9/'IS, end Y1'!D23) -> -60 | D23: 5 | E23: 0.2 | G23: 5 years depreciation plan (divide 300 $ of Asset value by 5 years)
A24: Less | B24: Labor (staff costs) | C24: =-(C9) -> -530
B25: EBIT | C25: =C20+C22+C23+C24 -> 10 | G25: Earning before interest and taxes (Pre-Tax Profit)
B27: KPI
B28: Profit Margin | C28: =C25/C20 -> 0.0125 | G28: EBIT/Revenues
A30: Less | B30: Interests | C30: =-(START!B21*START!C21) -> -25 | D30: =START!C21 -> 0.1 | G30: Interest on our debt (10% of $250)
B31: Pretax Earnings | C31: =C25+C30 -> -15
A34: Less | B34: Taxes | C34: =D34*C31 -> 0 | G34: 35% of EBT in US
B35: Net Income | C35: -10
B37: KPI
B38: Income per Share | C38: =C35/START!B8 -> -0.0066666667 | G38: Net Income / TOT 1,500 shares

Sheet IS, Y5
H1: Sales | I1: Price Increase | M1: Sales | N1: Price Increase | R1: Sales | S1: Price Increase | W1: Sales | X1: Price Increase
A2: A) | B2: ASSUPTIONS / PROJECTIONS (Annual) | G2: Growth assumptions | H2: 0.05 | I2: 0.05 | L2: Growth assumptions | M2: 0.05 | N2: 0.05 | Q2: Growth assumptions | R2: 0.05 | S2: 0.05 | V2: Growth assumptions | W2: 0.05 | X2: 0.05
B4: YEAR 1 | G4: YEAR 2 | L4: YEAR 3 | Q4: YEAR 4 | V4: YEAR 5
B6: Lemonade Stand (Tot) | C6: 1 | G6: Lemonade Stand (Tot) | H6: 2 | L6: Lemonade Stand (Tot) | M6: 3 | Q6: Lemonade Stand (Tot) | R6: 4 | V6: Lemonade Stand (Tot) | W6: 7
B7: SALES | C7: Nr | D7: Price | E7: Revenues | G7: SALES | H7: Nr | I7: Price | J7: Revenues | L7: SALES | M7: Nr | N7: Price | O7: Revenues | Q7: SALES | R7: Nr | S7: Price | T7: Revenues | V7: SALES | W7: Nr | X7: Price | Y7: Revenues
B8: Cups per stand | C8: 800 | D8: 1 | E8: =C8*D8 -> 800 | G8: Cups per stand | H8: =C8+C8*H2 -> 840 | I8: =D8+I2 -> 1.05 | J8: =H8*I8 -> 882 | L8: Cups per stand | M8: =H8+H8*M2 -> 882 | N8: =I8+N2 -> 1.1 | O8: =M8*N8 -> 970.2 | Q8: Cups per stand | R8: =M8+M8*R2 -> 926.1 | S8: =N8+S2 -> 1.15 | T8: =R8*S8 -> 1065.015 | V8: Cups per stand | W8: =R8+R8*W2 -> 972.405 | X8: =S8+X2 -> 1.2 | Y8: =W8*X8 -> 1166.886
B9: Tot Cups sold | C9: =C8 -> 800 | E9: =E8 -> 800 | G9: Tot Cups sold | H9: =H6*H8 -> 1680 | I9: =I8 -> 1.05 | J9: =H9*I9 -> 1764 | L9: Tot Cups sold | M9: =M6*M8 -> 2646 | N9: =N8 -> 1.1 | O9: =M9*N9 -> 2910.6 | Q9: Tot Cups sold | R9: =R6*R8 -> 3704.4 | S9: =S8 -> 1.15 | T9: =R9*S9 -> 4260.06 | V9: Tot Cups sold | W9: =W6*W8 -> 6806.835 | X9: =X8 -> 1.2 | Y9: =W9*X9 -> 8168.202
B12: COSTS | C12: Amount | G12: COSTS | H12: Amount | L12: COSTS | M12: Amount | Q12: COSTS | R12: Amount | V12: COSTS | W12: Amount
B13: Staff | C13: -530 | G13: Staff | H13: -1060 | L13: Staff | M13: -1590 | Q13: Staff | R13: -2120 | V13: Staff | W13: -3710 | Z13: <--- Small annual increase
B14: COGS | C14: =C26 -> -200 | G14: COGS | H14: -420 | L14: COGS | M14: -662 | Q14: COGS | R14: -926 | V14: COGS | W14: -1702 | Z14: <--- Small annual increase
B17: INCOME STATEMENT | G17: INCOME STATEMENT | L17: INCOME STATEMENT | Q17: INCOME STATEMENT | V17: INCOME STATEMENT
B19: # Lemonade Stands | C19: =C6 -> 1 | G19: # Lemonade Stands | H19: =H6 -> 2 | L19: Nr. Lemonade Stands | M19: =M6 -> 3 | Q19: Nr. Lemonade Stands | R19: =R6 -> 4 | V19: Nr. Lemonade Stands | W19: =W6 -> 7
B20: Cups sold (per stand) | C20: =C8 -> 800 | G20: Cups sold (per stand) | H20: =H8 -> 840 | L20: Cups sold (per stand) | M20: =M8 -> 882 | Q20: Cups sold (per stand) | R20: =R8 -> 926.1 | V20: Cups sold (per stand) | W20: =W8 -> 972.405
B21: Cups sold | C21: =C20*C19 -> 800 | G21: Cups sold | H21: =H20*H19 -> 1680 | L21: Cups sold | M21: =M20*M19 -> 2646 | Q21: Cups sold | R21: =R20*R19 -> 3704.4 | V21: Cups sold | W21: =W20*W19 -> 6806.835
B23: Price per cup | C23: =D8 -> 1 | G23: Price per cup | H23: =I8 -> 1.05 | L23: Price per cup | M23: =N8 -> 1.1 | Q23: Price per cup | R23: =S8 -> 1.15 | V23: Price per cup | W23: =X8 -> 1.2
B24: Revenues | C24: =C23*C21 -> 800 | G24: Revenues | H24: =H23*H21 -> 1764 | L24: Revenues | M24: =M23*M21 -> 2910.6 | Q24: Revenues | R24: =R23*R21 -> 4260.06 | V24: Revenues | W24: =W23*W21 -> 8168.202
A26: Less | B26: Cost of Goods Sold (COGS) | C26: =-('BS, Y! DAY 2'!C10) -> -200 | G26: Cost of Goods Sold (COGS) | H26: =H14 -> -420 | L26: Cost of Goods Sold (COGS) | M26: =M14 -> -662 | Q26: Cost of Goods Sold (COGS) | R26: =R14 -> -926 | V26: Cost of Goods Sold (COGS) | W26: =W14 -> -1702
A27: Less | B27: Depreciation | C27: =C66 -> -60 | G27: Depreciation | H27: =H66 -> -120 | L27: Depreciation | M27: =M66 -> -180 | Q27: Depreciation | R27: =R66 -> -240 | V27: Depreciation | W27: =W66 -> -420 | Z27: <-- depreciaton of $60 per stand every year
A28: Less | B28: Labor (staff costs) | C28: =C13 -> -530 | G28: Labor (staff costs) | H28: =H13 -> -1060 | L28: Labor (staff costs) | M28: =M13 -> -1590 | Q28: Labor (staff costs) | R28: =R13 -> -2120 | V28: Labor (staff costs) | W28: =W13 -> -3710
B29: EBIT | C29: =C24+C26+C27+C28 -> 10 | G29: EBIT | H29: =H24+H26+H27+H28 -> 164 | L29: EBIT | M29: =M24+M26+M27+M28 -> 478.6 | Q29: EBIT | R29: =R24+R26+R27+R28 -> 974.06 | V29: EBIT | W29: =W24+W26+W27+W28 -> 2336.202
B31: Profit Margin | C31: =C29/C24 -> 0.0125 | G31: Profit Margin | H31: =H29/H24 -> 0.092970522 | L31: Profit Margin | M31: =M29/M24 -> 0.16443345 | Q31: Profit Margin | R31: =R29/R24 -> 0.22864936 | V31: Profit Margin | W31: =W29/W24 -> 0.28601178
A33: Less | B33: Interests | C33: =-(START!B21*START!C21) -> -25 | D33: =START!C21 -> 0.1 | G33: Interests | H33: =C33 -> -25 | I33: =D33 -> 0.1 | L33: Interests | M33: =H33 -> -25 | N33: =I33 -> 0.1 | Q33: Interests | R33: =M33 -> -25 | S33: =N33 -> 0.1 | V33: Interests | W33: =R33 -> -25 | X33: =S33 -> 0.1
B34: EBT (Pretax Earnings) | C34: =C29+C33 -> -15 | G34: EBT (Pretax Earnings) | H34: =H29+H33 -> 139 | L34: EBT (Pretax Earnings) | M34: =M29+M33 -> 453.6 | Q34: EBT (Pretax Earnings) | R34: =R29+R33 -> 949.06 | V34: EBT (Pretax Earnings) | W34: =W29+W33 -> 2311.202
A37: Less | B37: Taxes | C37: =D37*C34 -> -5.25 | D37: 0.35 | G37: Taxes | H37: =I37*H34 -> 48.65 | I37: =D37 -> 0.35 | L37: Taxes | M37: =N37*M34 -> 158.76 | N37: =I37 -> 0.35 | Q37: Taxes | R37: =S37*R34 -> 332.171 | S37: =N37 -> 0.35 | V37: Taxes | W37: =X37*W34 -> 808.9207 | X37: =S37 -> 0.35
B38: Net Income (Profit) | C38: =C34-C37 -> -9.75 | G38: Net Income | H38: =H34-H37 -> 90.35 | L38: Net Income | M38: =M34-M37 -> 294.84 | Q38: Net Income | R38: =R34-R37 -> 616.889 | V38: Net Income | W38: =W34-W37 -> 1502.2813
B40: KPI | G40: KPI | L40: KPI | Q40: KPI | V40: KPI
B41: Income per Share | C41: =C38/START!B8 -> -0.0065 | G41: Income per Share | H41: =H38/START!B8 -> 0.060233333 | L41: Income per Share | M41: =M38/START!B16 -> 0.19656 | Q41: Income per Share | R41: =R38/1500 -> 0.41125933 | V41: Income per Share | W41: =W38/1500 -> 1.0015209
B42: (Profit) Growth | C42: na | G42: (Profit) Growth | H42: na | L42: (Profit) Growth | M42: =(M38-H38)/H38 -> 2.2633094 | Q42: (Profit) Growth | R42: =(R38-M38)/M38 -> 1.092284 | V42: (Profit) Growth | W42: =(W38-R38)/R38 -> 1.4352538
A47: B) | B47: PROFITS PER SHARE ANALYSIS
B49: Nr of Shares | C49: Shares allocation | E49: Original value | G49: After 5 years | H49: New Value
B50: 1000 | C50: =START!C6 -> 0.66666667 | D50: Owner | E50: =START!C11 -> 1 | G50: $1 of profit per share | H50: =B50+B50*W41 -> 2001.5209
B51: 500 | C51: =START!C7 -> 0.33333333 | D51: Investor | E51: =START!C11 -> 1 | G51: $1 of profit per share | H51: =B51+B51*W41 -> 1000.7604
A55: C) | B55: DEPRECIATION PLAN
B56: Lemonade Stand full price | C56: ='BS, Y! DAY 2'!C9 -> 300
A58: Stand | B58: YEAR 1 | E58: TOT | G58: YEAR 2 | L58: YEAR 3 | Q58: YEAR 4 | V58: YEAR 5
A59: 1 | B59: 300 | C59: -60 | E59: =B59+C59 -> 240 | G59: =E59 -> 240 | H59: -60 | I59: =G59+H59 -> 180 | J59: =SUM(I59:I66) -> 420 | L59: =I59 -> 180 | M59: -60 | N59: =L59+M59 -> 120 | O59: =SUM(N59:N66) -> 540 | Q59: =N59 -> 120 | R59: -60 | S59: =Q59+R59 -> 60 | T59: =SUM(S59:S66) -> 600 | V59: =S59 -> 60 | W59: -60 | X59: =V59+W59 -> 0 | Y59: =SUM(X59:X66) -> 1080
A60: 2 | G60: 300 | H60: -60 | I60: =G60+H60 -> 240 | L60: =I60 -> 240 | M60: -60 | N60: =L60+M60 -> 180 | Q60: =N60 -> 180 | R60: -60 | S60: =Q60+R60 -> 120 | V60: =S60 -> 120 | W60: -60 | X60: =V60+W60 -> 60
A61: 3 | L61: 300 | M61: -60 | N61: =L61+M61 -> 240 | Q61: =N61 -> 240 | R61: -60 | S61: =Q61+R61 -> 180 | V61: =S61 -> 180 | W61: -60 | X61: =V61+W61 -> 120
A62: 4 | Q62: 300 | R62: -60 | S62: =Q62+R62 -> 240 | V62: =S62 -> 240 | W62: -60 | X62: =V62+W62 -> 180
A63: 5 | V63: 300 | W63: -60 | X63: =V63+W63 -> 240
...

Sheet CF, Y5
B2: CASH FLOW STATEMENT
B5: CF | OPERATIONS | E5: Y1 | G5: Y2 | I5: Y3 | K5: Y4 | M5: Y5
B6: NET INCOME | E6: ='IS, Y5'!C38 -> -9.75 | G6: ='IS, Y5'!H38 -> 90.35 | I6: ='IS, Y5'!M38 -> 294.84 | K6: ='IS, Y5'!R38 -> 616.889 | M6: ='IS, Y5'!W38 -> 1502.2813
B7: (PLUS) DEPRECIATION | E7: =ABS('IS, Y5'!C27) -> 60 | G7: =ABS('IS, Y5'!H27) -> 120 | I7: =ABS('IS, Y5'!M27) -> 180 | K7: =ABS('IS, Y5'!R27) -> 240 | M7: =ABS('IS, Y5'!W27) -> 420
B8: CFO (Cash Flow of Operation) | E8: =E6+E7 -> 50.25 | G8: =G6+G7 -> 210.35 | I8: =I6+I7 -> 474.84 | K8: =K6+K7 -> 856.889 | M8: =M6+M7 -> 1922.2813
B10: CF | INVESTING
B11: CAPEX (Lemonade stands purchase costs) | E11: =-'BS, Y! DAY 2'!C21 -> -300 | G11: =E11*1 -> -300 | I11: =G11*1 -> -300 | K11: =-300*1 -> -300 | M11: =3*E11 -> -900 | O11: Note:Cost of new Lemonade Stands purchased
B12: CFI (Cash Flow of Investing) | E12: =E11 -> -300 | G12: =G11 -> -300 | I12: =I11 -> -300 | K12: =K11 -> -300 | M12: =M11 -> -900
B14: CF | FINANCING
B15: DEBT ISSUED | E15: ='BS, Y1 DAY 1'!C14 -> 250
B16: EQUITY ISSUED | E16: =START!B15 -> 500
B17: CFF (Cash Flow of Financing) | E17: =E15+E16 -> 750
B19: BEGINNING CASH | E19: 0 | G19: =E21 -> 500.25 | I19: =G21 -> 410.6 | K19: =I21 -> 585.44 | M19: =K21 -> 1142.329
B20: CHANGE IN CASH | E20: =E8+E12+E17 -> 500.25 | G20: =G8+G12+G17 -> -89.65 | I20: =I8+I12+I17 -> 174.84 | K20: =K8+K12+K17 -> 556.889 | M20: =M8+M12+M17 -> 1022.2813
B21: ENDING CASH | E21: =E20 -> 500.25 | G21: =G19+G20 -> 410.6 | I21: =I19+I20 -> 585.44 | K21: =K19+K20 -> 1142.329 | M21: =M19+M20 -> 2164.6103

Sheet BS, Y5
B2: BALANCE SHEET (updated, Y1-Y5)
B4: ASSETS | C4: Y1 | D4: Notes | F4: Y2 | H4: Y3 | J4: Y4 | L4: Y5
B5: Cash | C5: ='CF, Y5'!E21 -> 500.25 | D5: CF, end of Y1 | F5: ='CF, Y5'!G21 -> 410.6 | H5: ='CF, Y5'!I21 -> 585.44 | J5: ='CF, Y5'!K21 -> 1142.329 | L5: ='CF, Y5'!M21 -> 2164.6103
B6: Fixed assets | C6: ='BS, Y! DAY 2'!C9+'IS, end Y1'!C23 -> 240 | D6: Lemonade stand price minus depreciation (Y1) | F6: ='IS, Y5'!J59 -> 420 | H6: ='IS, Y5'!O59 -> 540 | J6: ='IS, Y5'!T59 -> 600 | L6: ='IS, Y5'!Y59 -> 1080
B7: Inventory | C7: 0 | D7: All goods sold | F7: 0 | H7: 0 | J7: 0 | L7: 0
B8: Goodwill | C8: ='BS, Y1 DAY 1'!C7 -> 1000 | D8: no changes | F8: =C8 -> 1000 | H8: =C8 -> 1000 | J8: =C8 -> 1000 | L8: =C8 -> 1000
B9: Total Assets | C9: =SUM(C5:C8) -> 1740.25 | F9: =SUM(F5:F8) -> 1830.6 | H9: =SUM(H5:H8) -> 2125.44 | J9: =SUM(J5:J8) -> 2742.329 | L9: =SUM(L5:L8) -> 4244.6103
B13: LIABILITIES
B14: Debt | C14: ='BS, Y1 DAY 1'!C13 -> 250 | F14: =C14 -> 250 | H14: =C14 -> 250 | J14: =C14 -> 250 | L14: =C14 -> 250
B15: Total Liability | C15: =C14 -> 250 | F15: =F14 -> 250 | H15: =H14 -> 250 | J15: =J14 -> 250 | L15: =L14 -> 250
B18: Shareholders Equity | C18: =1500+'IS, Y5'!C38 -> 1490.25 | D18: Tot Equity minus Y1 losses | F18: =C18+'CF, Y5'!G6 -> 1580.6 | H18: =F18+'CF, Y5'!I6 -> 1875.44 | J18: =H18+'CF, Y5'!K6 -> 2492.329 | L18: =J18+'CF, Y5'!M6 -> 3994.6103
B19: Per Share | C19: =C18/1500 -> 0.9935 | F19: =F18/1500 -> 1.0537333 | H19: =H18/1500 -> 1.2502933 | J19: =J18/1500 -> 1.6615527 | L19: =L18/1500 -> 2.6630735
B20: Growth | F20: =(F18-C18)/C18 -> 0.060627412 | H20: =(H18-F18)/F18 -> 0.18653676 | J20: =(J18-H18)/H18 -> 0.32893028 | L20: =(L18-J18)/J18 -> 0.60276204

Sheet EVALUATION
B1: EVALUATE THE BUSINESS
A3: A) | B3: EARNINGS YIELD
B4: Initial Value | C4: Y0
B5: Owner's equity (goodwill) | C5: 1000
B6: Equity investing | C6: 500
B7: TOT | C7: =SUM(C5:C6) -> 1500
C9: Y5
B10: NET INCOME | C10: ='IS, Y5'!W38 -> 1502.2813 | F10: After 5 years, the business earned $1,502. A Yield of 100%
B11: YIELD | C11: =C10/C7 -> 1.0015209
A14: B) | B14: RETURN ON CAPITAL | C14: Y5
C15: 2100 | F15: Spent for fixed assets (7 lemonade stand of $300)
C16: ='IS, Y5'!W29 -> 2336.202 | F16: Earned (EBIT) at Y5
B17: Return on Capital: | C17: =C16/C15 -> 1.1124771
A20: C) | B20: EARNING GROWTH
B21: Earnings per share growth | C21: Y2 | D21: Y5
C22: ='IS, Y5'!H41 -> 0.060233333 | D22: ='IS, Y5'!W41 -> 1.0015209
B23: CAGR (IRR) (Y2-Y5): | C23: =_xlfn.RRI(3,0.06,1) -> 1.5543648 | F23: CAGR Formula: IRR (3 years period, present value, future value)
A26: D) | B26: PROFITABILITY | C26: Y1 | D26: Y5
B27: Margins increased from | C27: ='IS, Y5'!C31 -> 0.0125 | D27: ='IS, Y5'!W31 -> 0.28601178
B31: LENDER POINT OF VIEW
F32: The difference is returns (betweeen Debt and equity) is due to the different risk.
B33: The lender lended: | C33: $250
B34: Annual return | C34: $25
B35: Annual interest rate | C35: 0.1
B36: ROI | C36: =25/250 -> 0.1 | D36: Low
B37: Risk: | C37: Low
B39: EQUITY INVESTOR POINT OF VIEW
B41: Money put up | C41: 500 | D41: ($1/share) | F41: The Lender has a priority return over equity (senior claim). Equity owner has the "Residual Claim".
B42: Annual return | C42: 500 | D42: ($1/share)
B44: ROI | C44: =C42/C41 -> 1 | D44: High
B45: Risk | C45: High
