Workbook

Sheet 📋 Instructions
A2: BUS 311 — Corporate Finance | Chapter 6: Bond Issuance & Financial Ratio Analysis [STUDENT VERSION]
A4: Assignment: Strategic Debt Offering — How Bond Issuance Shapes a Corporation's Financial Profile
A6: SCENARIO OVERVIEW
A7: You are a junior financial analyst at Meridian Industrial Corp (MRID), a regional manufacturing firm. The CFO is evaluating a $200 million senior unsecured bond offering to refinance short-term debt and fund capital expenditures. Your job is to: (1) price the bond issue, (2) model the financial impact under three deployment scenarios, and (3) deliver a data-driven recommendation to the CFO. Work through each tab in order — yellow cells are yours to complete. Read the formula hints carefully.
A11: YOUR TASKS BY TAB
A12: 📊 Company Baseline | B12: Given: Full income statement & balance sheet data. Your job: Build the IS subtotals (Gross Profit, EBIT, EBT, Net Income) and calculate 5 key financial ratios.
A13: 🔢 Bond Pricing | B13: Given: Bond assumptions (par, coupon, YTM, maturity). Your job: Build every pricing formula — semiannual coupon, PV of bond, YTM sensitivity table.
A14: 📈 Ratio Impact | B14: Given: Pre-offering financials. Your job: Model how the $200M offering changes the balance sheet under 3 scenarios, then compute post-offering ratios.
A15: 📋 CFO Dashboard | B15: Given: Blank scorecard. Your job: Link in your ratio results and write a 5-part CFO recommendation memo.
A18: COLOR CODING — READ THIS FIRST
A19: 🟡 YELLOW CELL | B19: You must enter a formula or value here. These are graded.
A20: 🟢 GREEN CELL | B20: Formula hint — read this for guidance on what to enter in the yellow cell above/beside it.
A21: Blue text | B21: Hard-coded INPUT provided for you — do not change these.
A22: Black text | B22: Formula already entered — do not edit.
A23: Green text | B23: Cross-sheet link pulling from another tab.
A25: GRADING RUBRIC
A26: Section | B26: What's Graded | J26: Points
A27: Tab 2 — Company Baseline | B27: IS formulas (4 cells) + 5 ratio formulas | J27: 20 pts
A28: Tab 3 — Bond Pricing | B28: 8 bond calculation formulas + sensitivity table (5 rows) | J28: 30 pts
A29: Tab 4 — Ratio Impact | B29: BS scenario adjustments (12 cells) + 5 ratio comparisons | J29: 25 pts
A30: Tab 5 — CFO Dashboard | B30: Cross-sheet links (8 cells) + written recommendation (5 prompts) | J30: 25 pts

Sheet 📊 Company Baseline
A1: Meridian Industrial Corp (MRID) — Pre-Offering Financial Statements (FY 2025)
A3: INCOME STATEMENT ($ thousands) | F3: FY 2025 ($000s) | G3: Formula Hint
A4: Revenue | F4: 425000 | G4: Given — hard-coded input
A5: Cost of Goods Sold | F5: 272000 | G5: Given — hard-coded input
A6: Gross Profit | G6: ✎ = Revenue − Cost of Goods Sold
A8: Selling, General & Admin | F8: 61000 | G8: Given
A9: Depreciation & Amortization | F9: 18500 | G9: Given
A10: EBIT (Operating Income) | G10: ✎ = Gross Profit − SG&A − D&A
A12: Interest Expense | F12: 9800 | G12: Given (stored as positive; represents $9.8M annual cost)
A13: EBT (Earnings Before Tax) | G13: ✎ = EBIT − Interest Expense
A14: Income Tax Expense (25%) | G14: ✎ = EBT × 25% tax rate (negative because it's a cost)
A15: Net Income | G15: ✎ = EBT + Tax (both already signed)
A22: BALANCE SHEET ($ thousands) — data provided; review before proceeding | F22: FY 2025 ($000s)
A23: ASSETS
A24: Cash & Cash Equivalents | F24: 32500
A25: Accounts Receivable | F25: 58000
A26: Inventory | F26: 44200
A27: Other Current Assets | F27: 8300
A28: Total Current Assets | F28: =SUM(F24:F27) -> 143000
A30: Property, Plant & Equipment (net) | F30: 312000
A31: Intangible Assets | F31: 22000
A32: Other Long-Term Assets | F32: 9500
A33: Total Assets | F33: =F28+F30+F31+F32 -> 486500
A36: LIABILITIES & EQUITY
A37: Accounts Payable | F37: 29400
A38: Short-Term Debt (Current) | F38: 45000
A39: Other Current Liabilities | F39: 13100
A40: Total Current Liabilities | F40: =SUM(F37:F39) -> 87500
A42: Long-Term Debt | F42: 110000
A43: Deferred Tax Liability | F43: 7200
A44: Total Liabilities | F44: =F40+F42+F43 -> 204700
A46: Common Stock & APIC | F46: 85000
A47: Retained Earnings | F47: 135800
A48: Total Equity | F48: =SUM(F46:F47) -> 220800
A49: Total Liabilities & Equity | F49: =F44+F48 -> 425500
A53: ★ PART 2 — YOUR TASK: Calculate Pre-Offering Financial Ratios (yellow cells = your formulas)
A54: Ratio Name | B54: Benchmark | C54: Result | D54: Formula Guidance
A55: Debt / Equity Ratio | B55: < 1.5x | D55: ✎ = (Short-Term Debt + Long-Term Debt) / Total Equity
A56: Debt / EBITDA | B56: < 3.0x | D56: ✎ = (ST Debt + LT Debt) / EBITDA; EBITDA = EBIT + D&A
A57: Interest Coverage (TIE) | B57: > 3.0x | D57: ✎ = EBIT / Interest Expense
...

Sheet 🔢 Bond Pricing
A1: MRID — Proposed Bond Offering: Pricing Model | ★ Build Every Formula
A3: STEP 1 — Bond Assumptions (given — blue = inputs, do NOT change)
A4: Assumption | B4: Value | C4: Context / Notes
A5: Face Value (Par) per Bond ($) | B5: 1000 | C5: Standard U.S. corporate bond par value
A6: Number of Bonds Issued | B6: 200000 | C6: Total offering size = Par × # Bonds = $200,000,000
A7: Annual Coupon Rate | B7: 0.055 | C7: MRID's stated coupon rate on the bond
A8: Market Yield to Maturity (YTM) | B8: 0.058 | C8: Current market rate investors demand for MRID's credit rating (BBB+)
A9: Years to Maturity | B9: 10 | C9: Bond matures in 10 years
A10: Payment Frequency (periods per year) | B10: 2 | C10: Standard: semiannual (2 payments per year)
A12: ★ STEP 2 — YOUR TASK: Build Each Bond Calculation Formula (yellow = your formula, green = hint)
A13: Metric | B13: Your Formula Cell | C13: Formula Structure Hint
A14: Semiannual Coupon Payment ($) | C14: ✎ = Par Value × Annual Coupon Rate ÷ Payment Frequency This is the cash payment MRID makes every 6 months per bond
A15: Semiannual Discount Rate | C15: ✎ = Annual YTM ÷ Payment Frequency You need this because coupons are paid every 6 months
A16: Total Number of Periods (n) | C16: ✎ = Years to Maturity × Payment Frequency Total semiannual periods over bond life
A17: Price per Bond [PV function] | C17: ✎ = PV(semiannual_rate, total_periods, −coupon_payment, −face_value) Excel syntax: =PV(C15, C16, -C14, -B5) The negatives on pmt and fv are because they are cash outflows to the issuer ⭐ This is the KEY formula — will it be at premium or discount?
A18: Premium / (Discount) per Bond | C18: ✎ = Price per Bond − Face Value Positive = premium (investors pay more); Negative = discount
A19: Total Offering Proceeds ($000s) | C19: ✎ = Price per Bond × Number of Bonds ÷ 1,000 Divide by 1,000 to express in $thousands like the financials
A20: Annual Interest Expense ($000s) | C20: ✎ = Par Value × Coupon Rate × Number of Bonds ÷ 1,000 This is what MRID pays in coupon interest each year
A21: Effective Annual Rate (EAR) | C21: ✎ = (1 + Semiannual Rate)² − 1 EAR > stated YTM because of semiannual compounding
A24: ★ STEP 3 — YOUR TASK: Yield Sensitivity Table (use PV formula with each YTM scenario)
A25: Scenario | B25: Market YTM | C25: Price per Bond | D25: Premium / (Discount) | E25: Total Proceeds ($000s) | F25: Interpretation
A26: Rates Fall (YTM = 4.5%) | B26: 0.045 | F26: Bond issued at PREMIUM — investors accept lower yield than coupon
A27: Par / Flat (YTM = 5.5%) | B27: 0.055 | F27: Bond priced at par — coupon rate equals market rate
A28: Base Case (YTM = 5.8%) | B28: 0.058 | F28: Student base case — slight DISCOUNT
A29: Rates Rise (YTM = 6.5%) | B29: 0.065 | F29: Discount widens — MRID raises less than $200M face value
A30: Stress Case (YTM = 7.5%) | B30: 0.075 | F30: Deep discount — borrowing cost rises significantly
A32: 💡 SENSITIVITY TABLE HINT — For each row, adapt your PV formula from Step 2 to use the YTM in column B of that row. Premium/(Discount): = [Price per Bond cell] - B5 Total Proceeds ($000s): = [Price per Bond cell] * B6 / 1000 Tip: Use absolute references ($B$5, $B$6, etc.) so you can copy the formula down!
A35: DISCUSSION QUESTIONS — type your answers in the yellow cells
A36: Q1: Why is MRID's bond priced BELOW par in the base case scenario? What does that mean for the company's total cost of borrowing?
A37: [ Type your answer here ]
A39: Q2: If interest rates spike to 7.5% after MRID issues the bond, who bears the financial risk? Explain your reasoning.
A40: [ Type your answer here ]
A42: Q3: Why does corporate America use semiannual coupons rather than annual payments? What's the investor's benefit?
A43: [ Type your answer here ]

Sheet 📈 Ratio Impact
A1: MRID — Post-Offering Financial Ratio Impact | ★ Model 3 Scenarios
A2: How does the $200M bond offering change MRID's financial ratios? You will model three different uses of the proceeds.
A4: SCENARIO DESCRIPTIONS — read carefully before building your formulas
A5: Scenario A — Refinance Short-Term Debt | B5: MRID uses ALL $200M to retire its revolving credit line (Short-Term Debt, currently $45M at 8.5% interest). Since $45M < $200M, assume the remaining $155M retires other ST obligations / reduces cash needs. Net effect: ST Debt → $0; LT Debt → +$200M; Total assets unchanged (debt-for-debt swap). Interest savings: lose 8.5% on $45M; pay 5.5% on $200M new bonds.
A6: Scenario B — Fund Capital Expenditure | B6: MRID uses ALL $200M to purchase new manufacturing equipment (PP&E). Net effect: LT Debt → +$200M; PP&E (net) → +$200M; Total assets increase by $200M. New D&A of ~$10M/yr assumed. Revenue and EBIT modestly improve (+2.5%). Interest expense increases by full $11M/yr (existing ST debt remains).
A7: Scenario C — Mixed Use ($100M each) | B7: MRID splits the proceeds: $100M retires all Short-Term Debt ($45M); $100M funds CapEx (PP&E). Net effect: ST Debt → $0; LT Debt → +$200M; PP&E → +$100M; Total assets increase by $100M. D&A increases ~$5M/yr. Blended interest savings/cost scenario. Revenue (1.5%) and EBIT (+1.2) modest improvements.
A10: ★ PART A — Post-Offering Balance Sheet (yellow = your formulas; pre-offering values are linked from Baseline tab)
A11: Line Item | B11: Pre-Offering ($000s) | C11: Scenario A | D11: Scenario B | E11: Scenario C | F11: What Should Change? (guide for your formula)
A12: Cash & Equivalents | B12: ='📊 Company Baseline'!F24 -> 32500 | C12: =$B$12 -> 32500 | D12: =$B$12 -> 32500 | E12: =$B$12 -> 32500 | F12: ✎ No change in any scenario — proceeds go to debt/PPE, not cash
A13: Short-Term Debt | B13: ='📊 Company Baseline'!F38 -> 45000 | D13: ='📊 Company Baseline'!F38 -> 45000 | F13: ✎ Scenario A: Retire ALL ST debt → $0. Scenario B: Unchanged → same as pre. Scenario C: Retire ALL ST debt → $0
A14: Long-Term Debt | B14: ='📊 Company Baseline'!F42 -> 110000 | F14: ✎ ALL scenarios: Add $200M new bond → LT Debt increases by $200,000
A15: PP&E (net) | B15: ='📊 Company Baseline'!$F$30 -> 312000 | C15: =B15 -> 312000 | F15: ✎ Scenario A: No change. Scenario B: +$200M CapEx. Scenario C: +$100M CapEx
A16: Total Equity | B16: ='📊 Company Baseline'!$F$48 -> 220800 | C16: ='📊 Company Baseline'!$F$48 -> 220800 | D16: ='📊 Company Baseline'!$F$48 -> 220800 | E16: ='📊 Company Baseline'!$F$48 -> 220800 | F16: ✎ No change — bond is DEBT, not equity. Equity = $220,800
A17: Total Debt (ST + LT) | B17: =B13+B14 -> 155000 | F17: ✎ = Short-Term Debt + Long-Term Debt for each scenario
A20: ★ PART B — Post-Offering Income Statement (yellow = your formulas)
A21: Item | B21: Pre-Offering | C21: Scenario A | D21: Scenario B | E21: Scenario C | F21: Key Assumption & Formula Hint
A22: Revenue | B22: ='📊 Company Baseline'!F4 -> 425000 | F22: ✎ Hint: Pre=B22, ScA=B22, ScB=B22*1.025, ScC=B22*1.015
A23: EBIT | B23: ='📊 Company Baseline'!F10 -> 0 | F23: ✎ Hint: ScA = same as pre; ScB = B23*1.025; ScC = B23*1.012
A24: D&A | B24: ='📊 Company Baseline'!F9 -> 18500 | F24: ✎ Hint: ScA = same; ScB = B24+10000; ScC = B24+5000
A25: EBITDA (EBIT + D&A) | B25: ='📊 Company Baseline'!F10+'📊 Company Baseline'!F9 -> 18500 | F25: ✎ Hint: =EBIT + D&A for each scenario.
A26: Interest Expense ($000s) | B26: ='📊 Company Baseline'!F12 -> 9800 | F26: ✎ Scen A: (110000*0.055+200000*0.055) [retired all ST] Scen B: (45000*0.085+110000*0.055+200000*0.055) [ST stays] Scen C: same as Scen A (all ST retired)
A27: Net Income ($000s) | B27: ='📊 Company Baseline'!F15 -> 0 | F27: ✎ =(EBIT + Interest Expense) × (1 − 0.25 tax rate)
A30: ★ PART C — Financial Ratio Comparison (all 20 ratio cells are yours)
A31: Ratio | B31: Pre-Offering | C31: Scenario A | D31: Scenario B | E31: Scenario C | F31: Benchmark | G31: Best? | H31: Formula Structure for Each Column
A32: Debt / Equity | F32: < 1.5x | H32: ✎ = (Short-Term Debt + Long-Term Debt) / Total Equity
A33: Debt / EBITDA | F33: < 3.0x | H33: ✎ = (ST Debt + LT Debt) / EBITDA; EBITDA = EBIT + D&A
A34: Interest Coverage (TIE) | F34: > 3.0x | H34: ✎ = EBIT / Interest Expense
A35: Net Debt / EBITDA | F35: < 2.5x | H35: ✎ = (Total Debt - Cash) / EBITDA
A36: Current Ratio | F36: > 1.5x | H36: ✎ = Total Current Assets / Total Current Liabilities
A38: ANALYSIS QUESTIONS — answer after completing your ratio table
A39: Q1: Which scenario results in the lowest Debt/EBITDA ratio? Why does that matter to a credit analyst?
A40: [ Type your answer here ]
A42: Q2: Under which scenario does Interest Coverage (TIE) improve vs. the pre-offering baseline? Explain why.
A43: [ Type your answer here ]
A45: Q3: How does each scenario affect the Current Ratio differently? Which scenario is best for short-term liquidity?
A46: [ Type your answer here ]

Sheet 📋 CFO Dashboard
A1: Meridian Industrial Corp — CFO Bond Offering Decision Dashboard
A2: Prepared by: [ Your Name ] | Date: [ Date ] | BUS 311 Corporate Finance
A4: ★ PART 1 — Ratio Scorecard (link each cell to your completed Ratio Impact tab — yellow = your cross-sheet links)
A5: Ratio | B5: Benchmark | C5: Pre-Offering | D5: Scenario A | E5: Scenario B | F5: Scenario C | G5: Best? | H5: Formula Hint (link from Ratio Impact tab)
A6: Debt / Equity | B6: < 1.5x | H6: ✎ Link cols C–G from '📈 Ratio Impact'!C32 through G32 Example col C: ='📈 Ratio Impact'!C32
A7: Debt / EBITDA | B7: < 3.0x | H7: ✎ Link cols C–G from '📈 Ratio Impact'!C33 through G33 Example col C: ='📈 Ratio Impact'!C33
A8: Interest Coverage | B8: > 3.0x | H8: ✎ Link cols C–G from '📈 Ratio Impact'!C34 through G34 Example col C: ='📈 Ratio Impact'!C34
A9: Net Debt / EBITDA | B9: < 2.5x | H9: ✎ Link cols C–G from '📈 Ratio Impact'!C35 through G35 Example col C: ='📈 Ratio Impact'!C35
A12: ★ PART 2 — Annual Debt Service Summary (link from your Ratio Impact IS section)
A13: Item | B13: Pre-Offering | D13: Scenario A | F13: Scenario B | H13: Scenario C
A14: Annual Interest Expense ($000s)
A15: EBIT ($000s)
A16: Net Income ($000s)
A17: Interest Coverage Ratio
A18: ✎ LINK -📈 Ratio Impact Tab
A20: ★ PART 3 — CFO Recommendation Memo (your written analysis — replace all placeholder text)
A21: 1. Recommended Scenario
A22: Guidance: State which scenario you recommend (A, B, or C) and write 2–3 sentences explaining your financial reasoning. Reference at least TWO specific ratios that support your choice.
A23: [ Type your answer here ]
A25: 2. Primary Financial Risk
A26: Guidance: Identify the biggest financial risk created by this bond offering. Which ratio is most affected? What threshold are you most concerned about breaching?
A27: [ Type your answer here ]
... A39: [ Type your answer here ]
