Workbook

Sheet Read Me
A1: BUS311 Capstone Milestone 3 | Read Me
A2: Build a source-traceable valuation that carries the Milestone 2 revenue hypothesis into base, upside, and downside decisions.
A3: Legend: blue font / pale yellow = student input | green font = cross-sheet link | black = formula | PASS/REVIEW/INCOMPLETE = control status, not a grade
A5: Student and project information
A6: Student name | D6: Workbook version | E6: 1.0
A7: Course section | D7: Updated | E7: 2026-07-29
A8: Company legal name | D8: Milestone points | E8: 8
A9: Ticker / exchange | D9: Primary outcomes | E9: LO4–LO6
A10: Fiscal year-end | D10: Forecast horizon | E10: Five annual periods
A11: Approved CFO decision | D11: Terminal method | E11: Gordon growth
A12: Prior milestone file | D12: Workbook status | E12: See Checks
A14: Required workflow
A15: 1 | B15: Revenue Handoff | C15: Transfer Milestone 2 history and final hypothesis | D15: Use the latest reported year as FY0 | E15: Three cases | F15: Evidence IDs | G15: CFO trigger | H15: Required
A16: 2 | B16: Inputs & Sources | C16: Enter operating and capital assumptions once | D16: Source IDs and rationale | E16: No magic numbers | F16: Market-value WACC | G16: Units | H16: Required
A17: 3 | B17: Scenario Forecasts | C17: Review revenue, EBIT, tax, NOPAT, D&A, CapEx, NWC, and UFCF | D17: Base/upside/downside | E17: Positive uses subtracted | F17: Five years | G17: No plugs | H17: Required
A18: 4 | B18: Valuation | C18: Review PV of forecast FCF and terminal value | D18: EV to equity bridge | E18: Debt and cash separate | F18: Per share | G18: Reasonableness | H18: Required
A19: 5 | B19: Decision Economics | C19: Use only for a discrete project or investment decision | D19: Incremental after-tax FCF | E19: NPV/IRR | F19: Fractional payback | G19: Guarded blanks | H19: As applicable
A20: 6 | B20: Sensitivities | C20: Test WACC and terminal growth | D20: Live formulas | E20: Center ties to base case | F20: Direction checks | G20: No pasted values | H20: Required
A21: 7 | B21: Board Appendix | C21: Select decision-useful outputs for the PPTX appendix | D21: Scenario valuation | E21: Revenue path | F21: Trigger | G21: Limitation | H21: Required
A22: 8 | B22: Checks & Sources | C22: Resolve incomplete/failed controls and explain review items | D22: Source every material input | E22: No formula errors | F22: Defend assumptions | G22: Submit workbook | H22: Required
A24: Milestone 3 rubric | 8 points
A25: Criterion | B25: Points | C25: Required evidence | D25: Scoring focus | F25: Integrity rules
A26: Revenue-to-forecast linkage and scenarios | B26: 2 | C26: Milestone 2 hypothesis, drivers, triggers, and three forecast paths | D26: Company-specific logic, not generic percentages | F26: Use SEC, FactSet, company IR, peer filings, and other credible evidence; AI output is not a financial source.
A27: DCF and decision mechanics | B27: 3 | C27: Correct tax/NOPAT, D&A, CapEx, ΔNWC, WACC, terminal value, EV-to-equity bridge, and payback if applicable | D27: Formula integrity, signs, and finance concepts | F27: Do not upload raw FactSet exports, private data, instructor content, or nonpublic information to a public AI tool.
A28: Sources, assumptions, and checks | B28: 2 | C28: Source IDs, definitions, dates, visible controls, and resolved model issues | D28: Auditability and honest limitations | F28: A passing control proves structure, not judgment. Explain unusual margins, growth, capital intensity, terminal assumptions, and scenario ordering.
A29: Board-ready decision output | B29: 1 | C29: Scenario outputs, sensitivity, trigger, takeaway, and limitation | D29: Useful CFO/Board evidence and Oral Presentation readiness | F29: The Excel model is graded here as a working milestone; selected outputs belong in the final PPTX appendix.

Sheet Revenue Handoff
A1: BUS311 Capstone Milestone 3 | Revenue Handoff
A2: Transfer the evidence-backed revenue history, final hypothesis, scenario drivers, and CFO triggers from Milestone 2.
A3: Legend: blue font / pale yellow = student input | green font = cross-sheet link | black = formula | PASS/REVIEW/INCOMPLETE = control status, not a grade
A5: Milestone 2 handoff
A6: Final revised revenue hypothesis
A7: Milestone 3 forecast and valuation handoff
A8: Approved CFO decision and stage / pause / modify / reject trigger
A10: Directional scenario bridge from Milestone 2
A11: Case | B11: Driver assumption | C11: Observable indicator / trigger | D11: Forecast revenue or margin effect | E11: Valuation channel | F11: CFO action / decision implication | G11: Evidence ID(s) | H11: Complete?
A12: Base | H12: =IF(COUNTIF(B12:G12,"?*")=6,"COMPLETE","INCOMPLETE") -> INCOMPLETE
A13: Upside | H13: =IF(COUNTIF(B13:G13,"?*")=6,"COMPLETE","INCOMPLETE") -> INCOMPLETE
A14: Downside | H14: =IF(COUNTIF(B14:G14,"?*")=6,"COMPLETE","INCOMPLETE") -> INCOMPLETE
A16: Revenue history transfer | copy from Milestone 2 Revenue History D5:H6
A17: Revenue line | B17: Definition / units | C17: Evidence ID(s)
A18: Fiscal year | B18: Oldest to newest; latest in H
A19: Reported total revenue | B19: Same units across years
A20: Year-over-year growth | B20: Calculated | E20: =IFERROR(E19/D19-1,"") | F20: =IFERROR(F19/E19-1,"") | G20: =IFERROR(G19/F19-1,"") | H20: =IFERROR(H19/G19-1,"")
A22: Control: the latest reported fiscal year and total revenue must be in H18:H19. Do not paste forecasts from Milestone 2; build them from the scenario assumptions in this workbook.

Sheet Inputs & Sources
A1: BUS311 Capstone Milestone 3 | Inputs & Sources
A2: Enter each assumption once, identify its source, and explain how it connects to the revenue engine or valuation method.
A3: Legend: blue font / pale yellow = student input | green font = cross-sheet link | black = formula | PASS/REVIEW/INCOMPLETE = control status, not a grade
A5: Global valuation inputs
A6: Input | B6: Value | C6: Units | D6: Source ID | E6: Rationale / definition / adjustment
A7: Valuation date | C7: date | E7: As-of date for market inputs
A8: Currency / model units | C8: text | E8: Use one scale throughout
A9: Latest actual fiscal year | B9: =IF('Revenue Handoff'!H18="","",'Revenue Handoff'!H18) | C9: FY | D9: =IF('Revenue Handoff'!C18="","",'Revenue Handoff'!C18) | E9: Linked from Revenue Handoff H18
A10: Latest actual revenue | B10: =IF('Revenue Handoff'!H19="","",'Revenue Handoff'!H19) | C10: model units | D10: =IF('Revenue Handoff'!C19="","",'Revenue Handoff'!C19) | E10: Linked from Revenue Handoff H19
A11: Latest actual operating NWC | C11: model units | E11: Operating current assets less operating current liabilities; exclude cash and debt
A12: Normalized cash tax rate | C12: % | E12: Use a defensible marginal/normalized cash tax rate; NOL benefits require separate support
A13: Risk-free rate | C13: % | E13: Maturity should be consistent with long-duration valuation
A14: Levered beta | C14: x | E14: Company or defensible peer-based beta
A15: Equity risk premium | C15: % | E15: Market risk premium used in CAPM
A16: Pre-tax cost of debt | C16: % | E16: Current marginal borrowing cost, not historical coupon
A17: Market value of equity | C17: model units | E17: Share price times diluted shares, as of valuation date
A18: Gross interest-bearing debt | C18: model units | E18: Current and long-term interest-bearing debt
A19: Cash and cash equivalents | C19: model units | E19: Use a consistent excess-cash convention and disclose it
A20: Diluted shares outstanding | C20: millions | E20: Use diluted, not basic, shares when appropriate
A21: Current share price | C21: per share | E21: As of valuation date; context only, not a required investment call
A23: Calculated discount rate and capital bridge
A24: Calculation | B24: Value | C24: Check / definition
A25: Cost of equity | B25: =IF(COUNT(B13:B15)<3,"",B13+B14*B15) | C25: Risk-free + beta × equity risk premium
A26: After-tax cost of debt | B26: =IF(OR(B16="",B12=""),"",B16*(1-B12)) | C26: Pre-tax cost × (1 − tax rate)
A27: Total market capital | B27: =IF(COUNT(B17:B18)<2,"",B17+B18) | C27: Market equity + gross debt
A28: Equity weight | B28: =IFERROR(B17/B27,"") | C28: Market equity / total capital
A29: Debt weight | B29: =IFERROR(B18/B27,"") | C29: Gross debt / total capital
A30: WACC | B30: =IF(COUNT(B28:B29)<2,"",B28*B25+B29*B16*(1-B12)) | C30: E/V × cost of equity + D/V × after-tax cost of debt
A31: Net debt | B31: =IF(COUNT(B18:B19)<2,"",B18-B19) | C31: Gross debt − cash
A32: Capital-weight check | B32: =IF(COUNT(B28:B29)<2,"",B28+B29) | C32: Equity weight + debt weight = 100%
A34: Scenario assumptions | link each row to a Milestone 2 driver, evidence item, or clearly labeled student assumption
A35: Case / assumption | B35: Source ID | C35: Driver link / rationale | E35: Year 1E | F35: Year 2E | G35: Year 3E | H35: Year 4E | I35: Year 5E | J35: Terminal
A36: Base | Revenue growth | C36: Base revenue-engine driver path
A37: Base | EBIT margin | C37: Explain the operating or capital-intensity rationale
A38: Base | D&A as % of revenue | C38: Explain the operating or capital-intensity rationale
A39: Base | CapEx as % of revenue | C39: Explain the operating or capital-intensity rationale
A40: Base | Operating NWC as % of revenue | C40: Explain the operating or capital-intensity rationale
A41: Base | Terminal growth rate | C41: Long-run growth consistent with a mature-state assumption
A44: Upside | Revenue growth | C44: Upside revenue-engine driver path
A45: Upside | EBIT margin | C45: Explain the operating or capital-intensity rationale
...

Sheet Scenario Forecasts
A1: BUS311 Capstone Milestone 3 | Scenario Forecasts
A2: Formula-driven unlevered cash flow for all three cases; expenses and investment rows are shown as positive uses and subtracted in FCF.
A3: Legend: blue font / pale yellow = student input | green font = cross-sheet link | black = formula | PASS/REVIEW/INCOMPLETE = control status, not a grade
A5: Base case | Revenue engine → unlevered free cash flow
A6: Fiscal year | B6: FY | C6: =IF('Inputs & Sources'!$B$9="","",'Inputs & Sources'!$B$9) | D6: =IF(C6="","",C6+1) | E6: =IF(D6="","",D6+1) | F6: =IF(E6="","",E6+1) | G6: =IF(F6="","",F6+1) | H6: =IF(G6="","",G6+1)
A7: Revenue growth | B7: % | D7: =IF(COUNT('Inputs & Sources'!E36)=0,"",'Inputs & Sources'!E36) | E7: =IF(COUNT('Inputs & Sources'!F36)=0,"",'Inputs & Sources'!F36) | F7: =IF(COUNT('Inputs & Sources'!G36)=0,"",'Inputs & Sources'!G36) | G7: =IF(COUNT('Inputs & Sources'!H36)=0,"",'Inputs & Sources'!H36) | H7: =IF(COUNT('Inputs & Sources'!I36)=0,"",'Inputs & Sources'!I36)
A8: Revenue | B8: model units | C8: =IF('Inputs & Sources'!$B$10="","",'Inputs & Sources'!$B$10) | D8: =IF(COUNT(C8,D7)<2,"",C8*(1+D7)) | E8: =IF(COUNT(D8,E7)<2,"",D8*(1+E7)) | F8: =IF(COUNT(E8,F7)<2,"",E8*(1+F7)) | G8: =IF(COUNT(F8,G7)<2,"",F8*(1+G7)) | H8: =IF(COUNT(G8,H7)<2,"",G8*(1+H7))
A9: EBIT margin | B9: % | D9: =IF(COUNT('Inputs & Sources'!E37)=0,"",'Inputs & Sources'!E37) | E9: =IF(COUNT('Inputs & Sources'!F37)=0,"",'Inputs & Sources'!F37) | F9: =IF(COUNT('Inputs & Sources'!G37)=0,"",'Inputs & Sources'!G37) | G9: =IF(COUNT('Inputs & Sources'!H37)=0,"",'Inputs & Sources'!H37) | H9: =IF(COUNT('Inputs & Sources'!I37)=0,"",'Inputs & Sources'!I37)
A10: EBIT | B10: model units | D10: =IF(OR(D8="",D9=""),"",D8*D9) | E10: =IF(OR(E8="",E9=""),"",E8*E9) | F10: =IF(OR(F8="",F9=""),"",F8*F9) | G10: =IF(OR(G8="",G9=""),"",G8*G9) | H10: =IF(OR(H8="",H9=""),"",H8*H9)
A11: Normalized cash tax rate | B11: % | D11: =IF('Inputs & Sources'!$B$12="","",'Inputs & Sources'!$B$12) | E11: =IF('Inputs & Sources'!$B$12="","",'Inputs & Sources'!$B$12) | F11: =IF('Inputs & Sources'!$B$12="","",'Inputs & Sources'!$B$12) | G11: =IF('Inputs & Sources'!$B$12="","",'Inputs & Sources'!$B$12) | H11: =IF('Inputs & Sources'!$B$12="","",'Inputs & Sources'!$B$12)
A12: Cash taxes on EBIT | B12: model units | D12: =IF(OR(D10="",D11=""),"",MAX(0,D10*D11)) | E12: =IF(OR(E10="",E11=""),"",MAX(0,E10*E11)) | F12: =IF(OR(F10="",F11=""),"",MAX(0,F10*F11)) | G12: =IF(OR(G10="",G11=""),"",MAX(0,G10*G11)) | H12: =IF(OR(H10="",H11=""),"",MAX(0,H10*H11))
A13: NOPAT | B13: model units | D13: =IF(D10="","",D10-D12) | E13: =IF(E10="","",E10-E12) | F13: =IF(F10="","",F10-F12) | G13: =IF(G10="","",G10-G12) | H13: =IF(H10="","",H10-H12)
A14: D&A as % of revenue | B14: % | D14: =IF(COUNT('Inputs & Sources'!E38)=0,"",'Inputs & Sources'!E38) | E14: =IF(COUNT('Inputs & Sources'!F38)=0,"",'Inputs & Sources'!F38) | F14: =IF(COUNT('Inputs & Sources'!G38)=0,"",'Inputs & Sources'!G38) | G14: =IF(COUNT('Inputs & Sources'!H38)=0,"",'Inputs & Sources'!H38) | H14: =IF(COUNT('Inputs & Sources'!I38)=0,"",'Inputs & Sources'!I38)
A15: D&A | B15: model units | D15: =IF(OR(D8="",D14=""),"",D8*D14) | E15: =IF(OR(E8="",E14=""),"",E8*E14) | F15: =IF(OR(F8="",F14=""),"",F8*F14) | G15: =IF(OR(G8="",G14=""),"",G8*G14) | H15: =IF(OR(H8="",H14=""),"",H8*H14)
A16: EBITDA | B16: model units | D16: =IF(D10="","",D10+D15) | E16: =IF(E10="","",E10+E15) | F16: =IF(F10="","",F10+F15) | G16: =IF(G10="","",G10+G15) | H16: =IF(H10="","",H10+H15)
A17: CapEx as % of revenue | B17: % | D17: =IF(COUNT('Inputs & Sources'!E39)=0,"",'Inputs & Sources'!E39) | E17: =IF(COUNT('Inputs & Sources'!F39)=0,"",'Inputs & Sources'!F39) | F17: =IF(COUNT('Inputs & Sources'!G39)=0,"",'Inputs & Sources'!G39) | G17: =IF(COUNT('Inputs & Sources'!H39)=0,"",'Inputs & Sources'!H39) | H17: =IF(COUNT('Inputs & Sources'!I39)=0,"",'Inputs & Sources'!I39)
A18: CapEx | positive cash use | B18: model units | D18: =IF(OR(D8="",D17=""),"",D8*D17) | E18: =IF(OR(E8="",E17=""),"",E8*E17) | F18: =IF(OR(F8="",F17=""),"",F8*F17) | G18: =IF(OR(G8="",G17=""),"",G8*G17) | H18: =IF(OR(H8="",H17=""),"",H8*H17)
A19: Operating NWC as % of revenue | B19: % | D19: =IF(COUNT('Inputs & Sources'!E40)=0,"",'Inputs & Sources'!E40) | E19: =IF(COUNT('Inputs & Sources'!F40)=0,"",'Inputs & Sources'!F40) | F19: =IF(COUNT('Inputs & Sources'!G40)=0,"",'Inputs & Sources'!G40) | G19: =IF(COUNT('Inputs & Sources'!H40)=0,"",'Inputs & Sources'!H40) | H19: =IF(COUNT('Inputs & Sources'!I40)=0,"",'Inputs & Sources'!I40)
A20: Operating NWC balance | B20: model units | C20: =IF('Inputs & Sources'!$B$11="","",'Inputs & Sources'!$B$11) | D20: =IF(OR(D8="",D19=""),"",D8*D19) | E20: =IF(OR(E8="",E19=""),"",E8*E19) | F20: =IF(OR(F8="",F19=""),"",F8*F19) | G20: =IF(OR(G8="",G19=""),"",G8*G19) | H20: =IF(OR(H8="",H19=""),"",H8*H19)
A21: Change in NWC | positive increase is a cash use | B21: model units | D21: =IF(OR(C20="",D20=""),"",D20-C20) | E21: =IF(OR(D20="",E20=""),"",E20-D20) | F21: =IF(OR(E20="",F20=""),"",F20-E20) | G21: =IF(OR(F20="",G20=""),"",G20-F20) | H21: =IF(OR(G20="",H20=""),"",H20-G20)
A22: Unlevered free cash flow | B22: model units | D22: =IF(COUNT(D13,D15,D18,D21)<4,"",D13+D15-D18-D21) | E22: =IF(COUNT(E13,E15,E18,E21)<4,"",E13+E15-E18-E21) | F22: =IF(COUNT(F13,F15,F18,F21)<4,"",F13+F15-F18-F21) | G22: =IF(COUNT(G13,G15,G18,G21)<4,"",G13+G15-G18-G21) | H22: =IF(COUNT(H13,H15,H18,H21)<4,"",H13+H15-H18-H21)
A23: Discount period | B23: years | D23: 1 | E23: 2 | F23: 3 | G23: 4 | H23: 5
A24: Discount factor | B24: x | D24: =IF('Inputs & Sources'!$B$30="","",1/(1+'Inputs & Sources'!$B$30)^D23) | E24: =IF('Inputs & Sources'!$B$30="","",1/(1+'Inputs & Sources'!$B$30)^E23) | F24: =IF('Inputs & Sources'!$B$30="","",1/(1+'Inputs & Sources'!$B$30)^F23) | G24: =IF('Inputs & Sources'!$B$30="","",1/(1+'Inputs & Sources'!$B$30)^G23) | H24: =IF('Inputs & Sources'!$B$30="","",1/(1+'Inputs & Sources'!$B$30)^H23)
A25: PV of unlevered FCF | B25: model units | D25: =IF(OR(D22="",D24=""),"",D22*D24) | E25: =IF(OR(E22="",E24=""),"",E22*E24) | F25: =IF(OR(F22="",F24=""),"",F22*F24) | G25: =IF(OR(G22="",G24=""),"",G22*G24) | H25: =IF(OR(H22="",H24=""),"",H22*H24)
A28: Upside case | Revenue engine → unlevered free cash flow
A29: Fiscal year | B29: FY | C29: =IF('Inputs & Sources'!$B$9="","",'Inputs & Sources'!$B$9) | D29: =IF(C29="","",C29+1) | E29: =IF(D29="","",D29+1) | F29: =IF(E29="","",E29+1) | G29: =IF(F29="","",F29+1) | H29: =IF(G29="","",G29+1)
A30: Revenue growth | B30: % | D30: =IF(COUNT('Inputs & Sources'!E44)=0,"",'Inputs & Sources'!E44) | E30: =IF(COUNT('Inputs & Sources'!F44)=0,"",'Inputs & Sources'!F44) | F30: =IF(COUNT('Inputs & Sources'!G44)=0,"",'Inputs & Sources'!G44) | G30: =IF(COUNT('Inputs & Sources'!H44)=0,"",'Inputs & Sources'!H44) | H30: =IF(COUNT('Inputs & Sources'!I44)=0,"",'Inputs & Sources'!I44)
A31: Revenue | B31: model units | C31: =IF('Inputs & Sources'!$B$10="","",'Inputs & Sources'!$B$10) | D31: =IF(COUNT(C31,D30)<2,"",C31*(1+D30)) | E31: =IF(COUNT(D31,E30)<2,"",D31*(1+E30)) | F31: =IF(COUNT(E31,F30)<2,"",E31*(1+F30)) | G31: =IF(COUNT(F31,G30)<2,"",F31*(1+G30)) | H31: =IF(COUNT(G31,H30)<2,"",G31*(1+H30))
A32: EBIT margin | B32: % | D32: =IF(COUNT('Inputs & Sources'!E45)=0,"",'Inputs & Sources'!E45) | E32: =IF(COUNT('Inputs & Sources'!F45)=0,"",'Inputs & Sources'!F45) | F32: =IF(COUNT('Inputs & Sources'!G45)=0,"",'Inputs & Sources'!G45) | G32: =IF(COUNT('Inputs & Sources'!H45)=0,"",'Inputs & Sources'!H45) | H32: =IF(COUNT('Inputs & Sources'!I45)=0,"",'Inputs & Sources'!I45)
A33: EBIT | B33: model units | D33: =IF(OR(D31="",D32=""),"",D31*D32) | E33: =IF(OR(E31="",E32=""),"",E31*E32) | F33: =IF(OR(F31="",F32=""),"",F31*F32) | G33: =IF(OR(G31="",G32=""),"",G31*G32) | H33: =IF(OR(H31="",H32=""),"",H31*H32)
A34: Normalized cash tax rate | B34: % | D34: =IF('Inputs & Sources'!$B$12="","",'Inputs & Sources'!$B$12) | E34: =IF('Inputs & Sources'!$B$12="","",'Inputs & Sources'!$B$12) | F34: =IF('Inputs & Sources'!$B$12="","",'Inputs & Sources'!$B$12) | G34: =IF('Inputs & Sources'!$B$12="","",'Inputs & Sources'!$B$12) | H34: =IF('Inputs & Sources'!$B$12="","",'Inputs & Sources'!$B$12)
A35: Cash taxes on EBIT | B35: model units | D35: =IF(OR(D33="",D34=""),"",MAX(0,D33*D34)) | E35: =IF(OR(E33="",E34=""),"",MAX(0,E33*E34)) | F35: =IF(OR(F33="",F34=""),"",MAX(0,F33*F34)) | G35: =IF(OR(G33="",G34=""),"",MAX(0,G33*G34)) | H35: =IF(OR(H33="",H34=""),"",MAX(0,H33*H34))
A36: NOPAT | B36: model units | D36: =IF(D33="","",D33-D35) | E36: =IF(E33="","",E33-E35) | F36: =IF(F33="","",F33-F35) | G36: =IF(G33="","",G33-G35) | H36: =IF(H33="","",H33-H35)
A37: D&A as % of revenue | B37: % | D37: =IF(COUNT('Inputs & Sources'!E46)=0,"",'Inputs & Sources'!E46) | E37: =IF(COUNT('Inputs & Sources'!F46)=0,"",'Inputs & Sources'!F46) | F37: =IF(COUNT('Inputs & Sources'!G46)=0,"",'Inputs & Sources'!G46) | G37: =IF(COUNT('Inputs & Sources'!H46)=0,"",'Inputs & Sources'!H46) | H37: =IF(COUNT('Inputs & Sources'!I46)=0,"",'Inputs & Sources'!I46)
A38: D&A | B38: model units | D38: =IF(OR(D31="",D37=""),"",D31*D37) | E38: =IF(OR(E31="",E37=""),"",E31*E37) | F38: =IF(OR(F31="",F37=""),"",F31*F37) | G38: =IF(OR(G31="",G37=""),"",G31*G37) | H38: =IF(OR(H31="",H37=""),"",H31*H37)
A39: EBITDA | B39: model units | D39: =IF(D33="","",D33+D38) | E39: =IF(E33="","",E33+E38) | F39: =IF(F33="","",F33+F38) | G39: =IF(G33="","",G33+G38) | H39: =IF(H33="","",H33+H38)
A40: CapEx as % of revenue | B40: % | D40: =IF(COUNT('Inputs & Sources'!E47)=0,"",'Inputs & Sources'!E47) | E40: =IF(COUNT('Inputs & Sources'!F47)=0,"",'Inputs & Sources'!F47) | F40: =IF(COUNT('Inputs & Sources'!G47)=0,"",'Inputs & Sources'!G47) | G40: =IF(COUNT('Inputs & Sources'!H47)=0,"",'Inputs & Sources'!H47) | H40: =IF(COUNT('Inputs & Sources'!I47)=0,"",'Inputs & Sources'!I47)
A41: CapEx | positive cash use | B41: model units | D41: =IF(OR(D31="",D40=""),"",D31*D40) | E41: =IF(OR(E31="",E40=""),"",E31*E40) | F41: =IF(OR(F31="",F40=""),"",F31*F40) | G41: =IF(OR(G31="",G40=""),"",G31*G40) | H41: =IF(OR(H31="",H40=""),"",H31*H40)
A42: Operating NWC as % of revenue | B42: % | D42: =IF(COUNT('Inputs & Sources'!E48)=0,"",'Inputs & Sources'!E48) | E42: =IF(COUNT('Inputs & Sources'!F48)=0,"",'Inputs & Sources'!F48) | F42: =IF(COUNT('Inputs & Sources'!G48)=0,"",'Inputs & Sources'!G48) | G42: =IF(COUNT('Inputs & Sources'!H48)=0,"",'Inputs & Sources'!H48) | H42: =IF(COUNT('Inputs & Sources'!I48)=0,"",'Inputs & Sources'!I48)
A43: Operating NWC balance | B43: model units | C43: =IF('Inputs & Sources'!$B$11="","",'Inputs & Sources'!$B$11) | D43: =IF(OR(D31="",D42=""),"",D31*D42) | E43: =IF(OR(E31="",E42=""),"",E31*E42) | F43: =IF(OR(F31="",F42=""),"",F31*F42) | G43: =IF(OR(G31="",G42=""),"",G31*G42) | H43: =IF(OR(H31="",H42=""),"",H31*H42)
...

Sheet Valuation
A1: BUS311 Capstone Milestone 3 | Valuation
A2: Gordon-growth DCF, enterprise-to-equity bridge, and decision-useful scenario outputs. This is supporting CFO evidence, not a required Buy/Hold/Sell call.
A3: Legend: blue font / pale yellow = student input | green font = cross-sheet link | black = formula | PASS/REVIEW/INCOMPLETE = control status, not a grade
A5: Scenario valuation summary
A6: Valuation bridge | B6: Units | C6: Base | D6: Upside | E6: Downside | F6: Decision use
A7: PV of forecast UFCF | B7: model units | C7: =IF(COUNT('Scenario Forecasts'!D25:H25)<5,"",SUM('Scenario Forecasts'!D25:H25)) | D7: =IF(COUNT('Scenario Forecasts'!D48:H48)<5,"",SUM('Scenario Forecasts'!D48:H48)) | E7: =IF(COUNT('Scenario Forecasts'!D71:H71)<5,"",SUM('Scenario Forecasts'!D71:H71))
A8: PV of terminal value | B8: model units | C8: =IF(OR('Scenario Forecasts'!H22="",'Inputs & Sources'!$B$30<='Inputs & Sources'!$J$41),"",('Scenario Forecasts'!H22*(1+'Inputs & Sources'!$J$41)/('Inputs & Sources'!$B$30-'Inputs & Sources'!$J$41))/(1+'Inputs & Sources'!$B$30)^5) | D8: =IF(OR('Scenario Forecasts'!H45="",'Inputs & Sources'!$B$30<='Inputs & Sources'!$J$49),"",('Scenario Forecasts'!H45*(1+'Inputs & Sources'!$J$49)/('Inputs & Sources'!$B$30-'Inputs & Sources'!$J$49))/(1+'Inputs & Sources'!$B$30)^5) | E8: =IF(OR('Scenario Forecasts'!H68="",'Inputs & Sources'!$B$30<='Inputs & Sources'!$J$57),"",('Scenario Forecasts'!H68*(1+'Inputs & Sources'!$J$57)/('Inputs & Sources'!$B$30-'Inputs & Sources'!$J$57))/(1+'Inputs & Sources'!$B$30)^5)
A9: Enterprise value | B9: model units | C9: =IF(COUNT(C7:C8)<2,"",SUM(C7:C8)) | D9: =IF(COUNT(D7:D8)<2,"",SUM(D7:D8)) | E9: =IF(COUNT(E7:E8)<2,"",SUM(E7:E8)) | F9: Value of operations
A10: Gross debt | B10: model units | C10: =IF('Inputs & Sources'!$B$18="","",'Inputs & Sources'!$B$18) | D10: =IF('Inputs & Sources'!$B$18="","",'Inputs & Sources'!$B$18) | E10: =IF('Inputs & Sources'!$B$18="","",'Inputs & Sources'!$B$18)
A11: Cash and equivalents | B11: model units | C11: =IF('Inputs & Sources'!$B$19="","",'Inputs & Sources'!$B$19) | D11: =IF('Inputs & Sources'!$B$19="","",'Inputs & Sources'!$B$19) | E11: =IF('Inputs & Sources'!$B$19="","",'Inputs & Sources'!$B$19)
A12: Equity value | B12: model units | C12: =IF(C9="","",C9-C10+C11) | D12: =IF(D9="","",D9-D10+D11) | E12: =IF(E9="","",E9-E10+E11) | F12: Enterprise value − debt + cash
A13: Diluted shares | B13: millions | C13: =IF('Inputs & Sources'!$B$20="","",'Inputs & Sources'!$B$20) | D13: =IF('Inputs & Sources'!$B$20="","",'Inputs & Sources'!$B$20) | E13: =IF('Inputs & Sources'!$B$20="","",'Inputs & Sources'!$B$20)
A14: Implied value per share | B14: per share | C14: =IFERROR(C12/C13,"") | D14: =IFERROR(D12/D13,"") | E14: =IFERROR(E12/E13,"") | F14: Scenario evidence for the CFO/Board
A15: Current share price | B15: per share | C15: =IF('Inputs & Sources'!$B$21="","",'Inputs & Sources'!$B$21) | D15: =IF('Inputs & Sources'!$B$21="","",'Inputs & Sources'!$B$21) | E15: =IF('Inputs & Sources'!$B$21="","",'Inputs & Sources'!$B$21)
A16: Implied upside / (downside) | B16: % | C16: =IFERROR(C14/C15-1,"") | D16: =IFERROR(D14/D15-1,"") | E16: =IFERROR(E14/E15-1,"")
A18: Terminal value reasonableness
A19: Metric | B19: Units | C19: Base | D19: Upside | E19: Downside | F19: Review question
A20: Terminal growth | B20: % | C20: =IF('Inputs & Sources'!$J$41="","",'Inputs & Sources'!$J$41) | D20: =IF('Inputs & Sources'!$J$49="","",'Inputs & Sources'!$J$49) | E20: =IF('Inputs & Sources'!$J$57="","",'Inputs & Sources'!$J$57) | F20: Is long-run growth defensible?
A21: WACC | B21: % | C21: =IF('Inputs & Sources'!$B$30="","",'Inputs & Sources'!$B$30) | D21: =IF('Inputs & Sources'!$B$30="","",'Inputs & Sources'!$B$30) | E21: =IF('Inputs & Sources'!$B$30="","",'Inputs & Sources'!$B$30) | F21: Does it reflect current market-value financing?
A22: Year 5 UFCF | B22: model units | C22: =IF('Scenario Forecasts'!H22="","",'Scenario Forecasts'!H22) | D22: =IF('Scenario Forecasts'!H45="","",'Scenario Forecasts'!H45) | E22: =IF('Scenario Forecasts'!H68="","",'Scenario Forecasts'!H68) | F22: Does cash flow reflect the operating case?
A23: Year 6 terminal FCF | B23: model units | C23: =IF(OR(C20="",C22=""),"",C22*(1+C20)) | D23: =IF(OR(D20="",D22=""),"",D22*(1+D20)) | E23: =IF(OR(E20="",E22=""),"",E22*(1+E20)) | F23: Year 5 FCF × (1 + g)
A24: Undiscounted terminal value | B24: model units | C24: =IF(OR(C21<=C20,C23=""),"",C23/(C21-C20)) | D24: =IF(OR(D21<=D20,D23=""),"",D23/(D21-D20)) | E24: =IF(OR(E21<=E20,E23=""),"",E23/(E21-E20)) | F24: Requires WACC > g
A25: PV of terminal value | B25: model units | C25: =IF(C24="","",C24/(1+C21)^5) | D25: =IF(D24="","",D24/(1+D21)^5) | E25: =IF(E24="","",E24/(1+E21)^5) | F25: Discounted on the same end-year convention
A26: PV terminal value / enterprise value | B26: % | C26: =IFERROR(C25/C9,"") | D26: =IFERROR(D25/D9,"") | E26: =IFERROR(E25/E9,"") | F26: High dependence requires explicit discussion
A27: Implied terminal EV / EBITDA | B27: x | C27: =IFERROR(C24/'Scenario Forecasts'!H16,"") | D27: =IFERROR(D24/'Scenario Forecasts'!H39,"") | E27: =IFERROR(E24/'Scenario Forecasts'!H62,"") | F27: Compare with company/peer economics; not a substitute for judgment
A28: WACC − terminal growth spread | B28: % | C28: =IF(COUNT(C20:C21)<2,"",C21-C20) | D28: =IF(COUNT(D20:D21)<2,"",D21-D20) | E28: =IF(COUNT(E20:E21)<2,"",E21-E20) | F28: A narrow spread magnifies value and risk

Sheet Decision Economics
A1: BUS311 Capstone Milestone 3 | Decision Economics
A2: Optional for a discrete investment decision. Uses after-tax incremental cash flow and fractional, guarded payback logic.
A3: Legend: blue font / pale yellow = student input | green font = cross-sheet link | black = formula | PASS/REVIEW/INCOMPLETE = control status, not a grade
A5: Applicability and project inputs
A6: Input | B6: Value | C6: Units | D6: Source ID | F6: When to use
A7: Applicable? | B7: No | C7: Yes / No | F7: Complete this schedule only when the approved CFO decision has a discrete incremental investment, acquisition, capacity, technology, or other project cash-flow path.
A8: Decision / project name | C8: text | F8: Depreciation
A9: Initial capital outlay | C9: model units | F9: The template calculates straight-line depreciation on the initial depreciable basis. If follow-on CapEx or tax depreciation is material, expand the schedule and source the method.
A10: Initial operating NWC investment | C10: model units | F10: Taxes
A11: Depreciable basis | C11: model units | F11: Cash taxes are not negative. Any immediate loss benefit or NOL utilization must be modeled and sourced separately.
A12: Useful life | C12: years | F12: Payback
A13: Terminal tax book value | C13: model units | F13: Payback uses undiscounted incremental FCF, reports a fractional year, handles exact zero, and returns No payback instead of an error.
A14: Tax rate | B14: =IF('Inputs & Sources'!$B$12="","",'Inputs & Sources'!$B$12) | C14: % | D14: linked | F14: Decision rule
A15: Discount rate | B15: =IF('Inputs & Sources'!$B$30="","",'Inputs & Sources'!$B$30) | C15: % | D15: linked | F15: NPV is the primary value-creation metric; IRR and payback are supporting constraints, not substitutes for strategy and risk.
A17: Incremental after-tax cash flow
A18: Line item | B18: Source ID | C18: Year 0 | D18: Year 1 | E18: Year 2 | F18: Year 3 | G18: Year 4 | H18: Year 5
A19: Incremental revenue
A20: Cash operating costs | positive use
A21: Straight-line depreciation | D21: =IF(OR($B$7<>"Yes",$B$11="",$B$12=""),"",IF(COLUMN()-3<=$B$12,($B$11-$B$13)/$B$12,0)) | E21: =IF(OR($B$7<>"Yes",$B$11="",$B$12=""),"",IF(COLUMN()-3<=$B$12,($B$11-$B$13)/$B$12,0)) | F21: =IF(OR($B$7<>"Yes",$B$11="",$B$12=""),"",IF(COLUMN()-3<=$B$12,($B$11-$B$13)/$B$12,0)) | G21: =IF(OR($B$7<>"Yes",$B$11="",$B$12=""),"",IF(COLUMN()-3<=$B$12,($B$11-$B$13)/$B$12,0)) | H21: =IF(OR($B$7<>"Yes",$B$11="",$B$12=""),"",IF(COLUMN()-3<=$B$12,($B$11-$B$13)/$B$12,0))
A22: EBIT | D22: =IF(COUNT(D19:D21)<3,"",D19-D20-D21) | E22: =IF(COUNT(E19:E21)<3,"",E19-E20-E21) | F22: =IF(COUNT(F19:F21)<3,"",F19-F20-F21) | G22: =IF(COUNT(G19:G21)<3,"",G19-G20-G21) | H22: =IF(COUNT(H19:H21)<3,"",H19-H20-H21)
A23: Cash taxes on EBIT | D23: =IF(OR(D22="",$B$14=""),"",MAX(0,D22*$B$14)) | E23: =IF(OR(E22="",$B$14=""),"",MAX(0,E22*$B$14)) | F23: =IF(OR(F22="",$B$14=""),"",MAX(0,F22*$B$14)) | G23: =IF(OR(G22="",$B$14=""),"",MAX(0,G22*$B$14)) | H23: =IF(OR(H22="",$B$14=""),"",MAX(0,H22*$B$14))
A24: NOPAT | D24: =IF(D22="","",D22-D23) | E24: =IF(E22="","",E22-E23) | F24: =IF(F22="","",F22-F23) | G24: =IF(G22="","",G22-G23) | H24: =IF(H22="","",H22-H23)
A25: Add: depreciation | D25: =IF(D21="","",D21) | E25: =IF(E21="","",E21) | F25: =IF(F21="","",F21) | G25: =IF(G21="","",G21) | H25: =IF(H21="","",H21)
A26: Capital expenditures | positive use | C26: =IF($B$7<>"Yes","",$B$9)
A27: Change in NWC | positive increase is a use
A28: Pre-tax salvage proceeds
A29: Tax book value at disposal | H29: =IF($B$7<>"Yes","",$B$13)
A30: After-tax salvage proceeds | H30: =IF(COUNT(H28,H29,$B$14)<3,"",H28-(H28-H29)*$B$14)
A31: NWC recovery
A32: Unlevered free cash flow | C32: =IF($B$7<>"Yes","",-C26-C27) | D32: =IF($B$7<>"Yes","",IF(COUNT(D24:D27)<4,"",SUM(D24:D25)-SUM(D26:D27)+SUM(D30:D31))) | E32: =IF($B$7<>"Yes","",IF(COUNT(E24:E27)<4,"",SUM(E24:E25)-SUM(E26:E27)+SUM(E30:E31))) | F32: =IF($B$7<>"Yes","",IF(COUNT(F24:F27)<4,"",SUM(F24:F25)-SUM(F26:F27)+SUM(F30:F31))) | G32: =IF($B$7<>"Yes","",IF(COUNT(G24:G27)<4,"",SUM(G24:G25)-SUM(G26:G27)+SUM(G30:G31))) | H32: =IF($B$7<>"Yes","",IF(COUNT(H24:H27)<4,"",SUM(H24:H25)-SUM(H26:H27)+SUM(H30:H31)))
A33: Cumulative cash flow | C33: =IF(C32="","",C32) | D33: =IF(D32="","",C33+D32) | E33: =IF(E32="","",D33+E32) | F33: =IF(F32="","",E33+F32) | G33: =IF(G32="","",F33+G32) | H33: =IF(H32="","",G33+H32)
A34: Payback-year contribution | D34: =IF($B$7<>"Yes","",IF(C33>=0,0,IF(D33<0,1,IFERROR(ABS(C33)/D32,0)))) | E34: =IF($B$7<>"Yes","",IF(D33>=0,0,IF(E33<0,1,IFERROR(ABS(D33)/E32,0)))) | F34: =IF($B$7<>"Yes","",IF(E33>=0,0,IF(F33<0,1,IFERROR(ABS(E33)/F32,0)))) | G34: =IF($B$7<>"Yes","",IF(F33>=0,0,IF(G33<0,1,IFERROR(ABS(F33)/G32,0)))) | H34: =IF($B$7<>"Yes","",IF(G33>=0,0,IF(H33<0,1,IFERROR(ABS(G33)/H32,0))))
A36: Decision metrics
A37: Metric | B37: Value | C37: Decision criterion | D37: Interpretation
A38: NPV | B38: =IF($B$7<>"Yes","",IF(COUNT(C32:H32)<6,"",C32+D32/(1+$B$15)^1+E32/(1+$B$15)^2+F32/(1+$B$15)^3+G32/(1+$B$15)^4+H32/(1+$B$15)^5)) | C38: NPV > 0 | D38: Value created above the required return
A39: IRR | B39: =IF(OR($B$7<>"Yes",COUNTIF(C32:H32,">0")=0,COUNTIF(C32:H32,"<0")=0),"",IRR(C32:H32)) | C39: IRR > discount rate | D39: Supporting rate-of-return evidence
A40: Undiscounted payback | B40: =IF($B$7<>"Yes","Not applicable",IF(COUNT(C32:H32)<6,"Incomplete",IF(MAX(D33:H33)<0,"No payback",SUM(D34:H34)))) -> Not applicable | C40: Within the approved liquidity/risk limit | D40: Supporting capital-at-risk evidence

Sheet Sensitivities
A1: BUS311 Capstone Milestone 3 | Sensitivities
A2: Value per share recalculated across WACC and terminal-growth assumptions; every table cell is formula-linked to the base-case FCF stream.
A3: Legend: blue font / pale yellow = student input | green font = cross-sheet link | black = formula | PASS/REVIEW/INCOMPLETE = control status, not a grade
A5: Base-case implied value per share | WACC × terminal growth
A6: WACC ↓ / terminal growth →
B7: =IF('Inputs & Sources'!$J$41="","",'Inputs & Sources'!$J$41-0.01) | C7: =IF('Inputs & Sources'!$J$41="","",'Inputs & Sources'!$J$41-0.005) | D7: =IF('Inputs & Sources'!$J$41="","",'Inputs & Sources'!$J$41+0) | E7: =IF('Inputs & Sources'!$J$41="","",'Inputs & Sources'!$J$41+0.005) | F7: =IF('Inputs & Sources'!$J$41="","",'Inputs & Sources'!$J$41+0.01) | G7: Check: higher WACC lowers value; higher g raises value. Center cell = base case.
A8: =IF('Inputs & Sources'!$B$30="","",'Inputs & Sources'!$B$30-0.02) | B8: =IF(OR($A8="",B$7="",$A8<=B$7,'Inputs & Sources'!$B$20<=0,COUNT('Scenario Forecasts'!$D$22:$H$22)<5),"",(('Scenario Forecasts'!$D$22/(1+$A8)^1+'Scenario Forecasts'!$E$22/(1+$A8)^2+'Scenario Forecasts'!$F$22/(1+$A8)^3+'Scenario Forecasts'!$G$22/(1+$A8)^4+'Scenario Forecasts'!$H$22/(1+$A8)^5)+('Scenario Forecasts'!$H$22*(1+B$7)/($A8-B$7))/(1+$A8)^5-'Inputs & Sources'!$B$18+'Inputs & Sources'!$B$19)/'Inputs & Sources'!$B$20) | C8: =IF(OR($A8="",C$7="",$A8<=C$7,'Inputs & Sources'!$B$20<=0,COUNT('Scenario Forecasts'!$D$22:$H$22)<5),"",(('Scenario Forecasts'!$D$22/(1+$A8)^1+'Scenario Forecasts'!$E$22/(1+$A8)^2+'Scenario Forecasts'!$F$22/(1+$A8)^3+'Scenario Forecasts'!$G$22/(1+$A8)^4+'Scenario Forecasts'!$H$22/(1+$A8)^5)+('Scenario Forecasts'!$H$22*(1+C$7)/($A8-C$7))/(1+$A8)^5-'Inputs & Sources'!$B$18+'Inputs & Sources'!$B$19)/'Inputs & Sources'!$B$20) | D8: =IF(OR($A8="",D$7="",$A8<=D$7,'Inputs & Sources'!$B$20<=0,COUNT('Scenario Forecasts'!$D$22:$H$22)<5),"",(('Scenario Forecasts'!$D$22/(1+$A8)^1+'Scenario Forecasts'!$E$22/(1+$A8)^2+'Scenario Forecasts'!$F$22/(1+$A8)^3+'Scenario Forecasts'!$G$22/(1+$A8)^4+'Scenario Forecasts'!$H$22/(1+$A8)^5)+('Scenario Forecasts'!$H$22*(1+D$7)/($A8-D$7))/(1+$A8)^5-'Inputs & Sources'!$B$18+'Inputs & Sources'!$B$19)/'Inputs & Sources'!$B$20) | E8: =IF(OR($A8="",E$7="",$A8<=E$7,'Inputs & Sources'!$B$20<=0,COUNT('Scenario Forecasts'!$D$22:$H$22)<5),"",(('Scenario Forecasts'!$D$22/(1+$A8)^1+'Scenario Forecasts'!$E$22/(1+$A8)^2+'Scenario Forecasts'!$F$22/(1+$A8)^3+'Scenario Forecasts'!$G$22/(1+$A8)^4+'Scenario Forecasts'!$H$22/(1+$A8)^5)+('Scenario Forecasts'!$H$22*(1+E$7)/($A8-E$7))/(1+$A8)^5-'Inputs & Sources'!$B$18+'Inputs & Sources'!$B$19)/'Inputs & Sources'!$B$20) | F8: =IF(OR($A8="",F$7="",$A8<=F$7,'Inputs & Sources'!$B$20<=0,COUNT('Scenario Forecasts'!$D$22:$H$22)<5),"",(('Scenario Forecasts'!$D$22/(1+$A8)^1+'Scenario Forecasts'!$E$22/(1+$A8)^2+'Scenario Forecasts'!$F$22/(1+$A8)^3+'Scenario Forecasts'!$G$22/(1+$A8)^4+'Scenario Forecasts'!$H$22/(1+$A8)^5)+('Scenario Forecasts'!$H$22*(1+F$7)/($A8-F$7))/(1+$A8)^5-'Inputs & Sources'!$B$18+'Inputs & Sources'!$B$19)/'Inputs & Sources'!$B$20)
A9: =IF('Inputs & Sources'!$B$30="","",'Inputs & Sources'!$B$30-0.01) | B9: =IF(OR($A9="",B$7="",$A9<=B$7,'Inputs & Sources'!$B$20<=0,COUNT('Scenario Forecasts'!$D$22:$H$22)<5),"",(('Scenario Forecasts'!$D$22/(1+$A9)^1+'Scenario Forecasts'!$E$22/(1+$A9)^2+'Scenario Forecasts'!$F$22/(1+$A9)^3+'Scenario Forecasts'!$G$22/(1+$A9)^4+'Scenario Forecasts'!$H$22/(1+$A9)^5)+('Scenario Forecasts'!$H$22*(1+B$7)/($A9-B$7))/(1+$A9)^5-'Inputs & Sources'!$B$18+'Inputs & Sources'!$B$19)/'Inputs & Sources'!$B$20) | C9: =IF(OR($A9="",C$7="",$A9<=C$7,'Inputs & Sources'!$B$20<=0,COUNT('Scenario Forecasts'!$D$22:$H$22)<5),"",(('Scenario Forecasts'!$D$22/(1+$A9)^1+'Scenario Forecasts'!$E$22/(1+$A9)^2+'Scenario Forecasts'!$F$22/(1+$A9)^3+'Scenario Forecasts'!$G$22/(1+$A9)^4+'Scenario Forecasts'!$H$22/(1+$A9)^5)+('Scenario Forecasts'!$H$22*(1+C$7)/($A9-C$7))/(1+$A9)^5-'Inputs & Sources'!$B$18+'Inputs & Sources'!$B$19)/'Inputs & Sources'!$B$20) | D9: =IF(OR($A9="",D$7="",$A9<=D$7,'Inputs & Sources'!$B$20<=0,COUNT('Scenario Forecasts'!$D$22:$H$22)<5),"",(('Scenario Forecasts'!$D$22/(1+$A9)^1+'Scenario Forecasts'!$E$22/(1+$A9)^2+'Scenario Forecasts'!$F$22/(1+$A9)^3+'Scenario Forecasts'!$G$22/(1+$A9)^4+'Scenario Forecasts'!$H$22/(1+$A9)^5)+('Scenario Forecasts'!$H$22*(1+D$7)/($A9-D$7))/(1+$A9)^5-'Inputs & Sources'!$B$18+'Inputs & Sources'!$B$19)/'Inputs & Sources'!$B$20) | E9: =IF(OR($A9="",E$7="",$A9<=E$7,'Inputs & Sources'!$B$20<=0,COUNT('Scenario Forecasts'!$D$22:$H$22)<5),"",(('Scenario Forecasts'!$D$22/(1+$A9)^1+'Scenario Forecasts'!$E$22/(1+$A9)^2+'Scenario Forecasts'!$F$22/(1+$A9)^3+'Scenario Forecasts'!$G$22/(1+$A9)^4+'Scenario Forecasts'!$H$22/(1+$A9)^5)+('Scenario Forecasts'!$H$22*(1+E$7)/($A9-E$7))/(1+$A9)^5-'Inputs & Sources'!$B$18+'Inputs & Sources'!$B$19)/'Inputs & Sources'!$B$20) | F9: =IF(OR($A9="",F$7="",$A9<=F$7,'Inputs & Sources'!$B$20<=0,COUNT('Scenario Forecasts'!$D$22:$H$22)<5),"",(('Scenario Forecasts'!$D$22/(1+$A9)^1+'Scenario Forecasts'!$E$22/(1+$A9)^2+'Scenario Forecasts'!$F$22/(1+$A9)^3+'Scenario Forecasts'!$G$22/(1+$A9)^4+'Scenario Forecasts'!$H$22/(1+$A9)^5)+('Scenario Forecasts'!$H$22*(1+F$7)/($A9-F$7))/(1+$A9)^5-'Inputs & Sources'!$B$18+'Inputs & Sources'!$B$19)/'Inputs & Sources'!$B$20)
A10: =IF('Inputs & Sources'!$B$30="","",'Inputs & Sources'!$B$30+0) | B10: =IF(OR($A10="",B$7="",$A10<=B$7,'Inputs & Sources'!$B$20<=0,COUNT('Scenario Forecasts'!$D$22:$H$22)<5),"",(('Scenario Forecasts'!$D$22/(1+$A10)^1+'Scenario Forecasts'!$E$22/(1+$A10)^2+'Scenario Forecasts'!$F$22/(1+$A10)^3+'Scenario Forecasts'!$G$22/(1+$A10)^4+'Scenario Forecasts'!$H$22/(1+$A10)^5)+('Scenario Forecasts'!$H$22*(1+B$7)/($A10-B$7))/(1+$A10)^5-'Inputs & Sources'!$B$18+'Inputs & Sources'!$B$19)/'Inputs & Sources'!$B$20) | C10: =IF(OR($A10="",C$7="",$A10<=C$7,'Inputs & Sources'!$B$20<=0,COUNT('Scenario Forecasts'!$D$22:$H$22)<5),"",(('Scenario Forecasts'!$D$22/(1+$A10)^1+'Scenario Forecasts'!$E$22/(1+$A10)^2+'Scenario Forecasts'!$F$22/(1+$A10)^3+'Scenario Forecasts'!$G$22/(1+$A10)^4+'Scenario Forecasts'!$H$22/(1+$A10)^5)+('Scenario Forecasts'!$H$22*(1+C$7)/($A10-C$7))/(1+$A10)^5-'Inputs & Sources'!$B$18+'Inputs & Sources'!$B$19)/'Inputs & Sources'!$B$20) | D10: =IF(OR($A10="",D$7="",$A10<=D$7,'Inputs & Sources'!$B$20<=0,COUNT('Scenario Forecasts'!$D$22:$H$22)<5),"",(('Scenario Forecasts'!$D$22/(1+$A10)^1+'Scenario Forecasts'!$E$22/(1+$A10)^2+'Scenario Forecasts'!$F$22/(1+$A10)^3+'Scenario Forecasts'!$G$22/(1+$A10)^4+'Scenario Forecasts'!$H$22/(1+$A10)^5)+('Scenario Forecasts'!$H$22*(1+D$7)/($A10-D$7))/(1+$A10)^5-'Inputs & Sources'!$B$18+'Inputs & Sources'!$B$19)/'Inputs & Sources'!$B$20) | E10: =IF(OR($A10="",E$7="",$A10<=E$7,'Inputs & Sources'!$B$20<=0,COUNT('Scenario Forecasts'!$D$22:$H$22)<5),"",(('Scenario Forecasts'!$D$22/(1+$A10)^1+'Scenario Forecasts'!$E$22/(1+$A10)^2+'Scenario Forecasts'!$F$22/(1+$A10)^3+'Scenario Forecasts'!$G$22/(1+$A10)^4+'Scenario Forecasts'!$H$22/(1+$A10)^5)+('Scenario Forecasts'!$H$22*(1+E$7)/($A10-E$7))/(1+$A10)^5-'Inputs & Sources'!$B$18+'Inputs & Sources'!$B$19)/'Inputs & Sources'!$B$20) | F10: =IF(OR($A10="",F$7="",$A10<=F$7,'Inputs & Sources'!$B$20<=0,COUNT('Scenario Forecasts'!$D$22:$H$22)<5),"",(('Scenario Forecasts'!$D$22/(1+$A10)^1+'Scenario Forecasts'!$E$22/(1+$A10)^2+'Scenario Forecasts'!$F$22/(1+$A10)^3+'Scenario Forecasts'!$G$22/(1+$A10)^4+'Scenario Forecasts'!$H$22/(1+$A10)^5)+('Scenario Forecasts'!$H$22*(1+F$7)/($A10-F$7))/(1+$A10)^5-'Inputs & Sources'!$B$18+'Inputs & Sources'!$B$19)/'Inputs & Sources'!$B$20)
A11: =IF('Inputs & Sources'!$B$30="","",'Inputs & Sources'!$B$30+0.01) | B11: =IF(OR($A11="",B$7="",$A11<=B$7,'Inputs & Sources'!$B$20<=0,COUNT('Scenario Forecasts'!$D$22:$H$22)<5),"",(('Scenario Forecasts'!$D$22/(1+$A11)^1+'Scenario Forecasts'!$E$22/(1+$A11)^2+'Scenario Forecasts'!$F$22/(1+$A11)^3+'Scenario Forecasts'!$G$22/(1+$A11)^4+'Scenario Forecasts'!$H$22/(1+$A11)^5)+('Scenario Forecasts'!$H$22*(1+B$7)/($A11-B$7))/(1+$A11)^5-'Inputs & Sources'!$B$18+'Inputs & Sources'!$B$19)/'Inputs & Sources'!$B$20) | C11: =IF(OR($A11="",C$7="",$A11<=C$7,'Inputs & Sources'!$B$20<=0,COUNT('Scenario Forecasts'!$D$22:$H$22)<5),"",(('Scenario Forecasts'!$D$22/(1+$A11)^1+'Scenario Forecasts'!$E$22/(1+$A11)^2+'Scenario Forecasts'!$F$22/(1+$A11)^3+'Scenario Forecasts'!$G$22/(1+$A11)^4+'Scenario Forecasts'!$H$22/(1+$A11)^5)+('Scenario Forecasts'!$H$22*(1+C$7)/($A11-C$7))/(1+$A11)^5-'Inputs & Sources'!$B$18+'Inputs & Sources'!$B$19)/'Inputs & Sources'!$B$20) | D11: =IF(OR($A11="",D$7="",$A11<=D$7,'Inputs & Sources'!$B$20<=0,COUNT('Scenario Forecasts'!$D$22:$H$22)<5),"",(('Scenario Forecasts'!$D$22/(1+$A11)^1+'Scenario Forecasts'!$E$22/(1+$A11)^2+'Scenario Forecasts'!$F$22/(1+$A11)^3+'Scenario Forecasts'!$G$22/(1+$A11)^4+'Scenario Forecasts'!$H$22/(1+$A11)^5)+('Scenario Forecasts'!$H$22*(1+D$7)/($A11-D$7))/(1+$A11)^5-'Inputs & Sources'!$B$18+'Inputs & Sources'!$B$19)/'Inputs & Sources'!$B$20) | E11: =IF(OR($A11="",E$7="",$A11<=E$7,'Inputs & Sources'!$B$20<=0,COUNT('Scenario Forecasts'!$D$22:$H$22)<5),"",(('Scenario Forecasts'!$D$22/(1+$A11)^1+'Scenario Forecasts'!$E$22/(1+$A11)^2+'Scenario Forecasts'!$F$22/(1+$A11)^3+'Scenario Forecasts'!$G$22/(1+$A11)^4+'Scenario Forecasts'!$H$22/(1+$A11)^5)+('Scenario Forecasts'!$H$22*(1+E$7)/($A11-E$7))/(1+$A11)^5-'Inputs & Sources'!$B$18+'Inputs & Sources'!$B$19)/'Inputs & Sources'!$B$20) | F11: =IF(OR($A11="",F$7="",$A11<=F$7,'Inputs & Sources'!$B$20<=0,COUNT('Scenario Forecasts'!$D$22:$H$22)<5),"",(('Scenario Forecasts'!$D$22/(1+$A11)^1+'Scenario Forecasts'!$E$22/(1+$A11)^2+'Scenario Forecasts'!$F$22/(1+$A11)^3+'Scenario Forecasts'!$G$22/(1+$A11)^4+'Scenario Forecasts'!$H$22/(1+$A11)^5)+('Scenario Forecasts'!$H$22*(1+F$7)/($A11-F$7))/(1+$A11)^5-'Inputs & Sources'!$B$18+'Inputs & Sources'!$B$19)/'Inputs & Sources'!$B$20)
A12: =IF('Inputs & Sources'!$B$30="","",'Inputs & Sources'!$B$30+0.02) | B12: =IF(OR($A12="",B$7="",$A12<=B$7,'Inputs & Sources'!$B$20<=0,COUNT('Scenario Forecasts'!$D$22:$H$22)<5),"",(('Scenario Forecasts'!$D$22/(1+$A12)^1+'Scenario Forecasts'!$E$22/(1+$A12)^2+'Scenario Forecasts'!$F$22/(1+$A12)^3+'Scenario Forecasts'!$G$22/(1+$A12)^4+'Scenario Forecasts'!$H$22/(1+$A12)^5)+('Scenario Forecasts'!$H$22*(1+B$7)/($A12-B$7))/(1+$A12)^5-'Inputs & Sources'!$B$18+'Inputs & Sources'!$B$19)/'Inputs & Sources'!$B$20) | C12: =IF(OR($A12="",C$7="",$A12<=C$7,'Inputs & Sources'!$B$20<=0,COUNT('Scenario Forecasts'!$D$22:$H$22)<5),"",(('Scenario Forecasts'!$D$22/(1+$A12)^1+'Scenario Forecasts'!$E$22/(1+$A12)^2+'Scenario Forecasts'!$F$22/(1+$A12)^3+'Scenario Forecasts'!$G$22/(1+$A12)^4+'Scenario Forecasts'!$H$22/(1+$A12)^5)+('Scenario Forecasts'!$H$22*(1+C$7)/($A12-C$7))/(1+$A12)^5-'Inputs & Sources'!$B$18+'Inputs & Sources'!$B$19)/'Inputs & Sources'!$B$20) | D12: =IF(OR($A12="",D$7="",$A12<=D$7,'Inputs & Sources'!$B$20<=0,COUNT('Scenario Forecasts'!$D$22:$H$22)<5),"",(('Scenario Forecasts'!$D$22/(1+$A12)^1+'Scenario Forecasts'!$E$22/(1+$A12)^2+'Scenario Forecasts'!$F$22/(1+$A12)^3+'Scenario Forecasts'!$G$22/(1+$A12)^4+'Scenario Forecasts'!$H$22/(1+$A12)^5)+('Scenario Forecasts'!$H$22*(1+D$7)/($A12-D$7))/(1+$A12)^5-'Inputs & Sources'!$B$18+'Inputs & Sources'!$B$19)/'Inputs & Sources'!$B$20) | E12: =IF(OR($A12="",E$7="",$A12<=E$7,'Inputs & Sources'!$B$20<=0,COUNT('Scenario Forecasts'!$D$22:$H$22)<5),"",(('Scenario Forecasts'!$D$22/(1+$A12)^1+'Scenario Forecasts'!$E$22/(1+$A12)^2+'Scenario Forecasts'!$F$22/(1+$A12)^3+'Scenario Forecasts'!$G$22/(1+$A12)^4+'Scenario Forecasts'!$H$22/(1+$A12)^5)+('Scenario Forecasts'!$H$22*(1+E$7)/($A12-E$7))/(1+$A12)^5-'Inputs & Sources'!$B$18+'Inputs & Sources'!$B$19)/'Inputs & Sources'!$B$20) | F12: =IF(OR($A12="",F$7="",$A12<=F$7,'Inputs & Sources'!$B$20<=0,COUNT('Scenario Forecasts'!$D$22:$H$22)<5),"",(('Scenario Forecasts'!$D$22/(1+$A12)^1+'Scenario Forecasts'!$E$22/(1+$A12)^2+'Scenario Forecasts'!$F$22/(1+$A12)^3+'Scenario Forecasts'!$G$22/(1+$A12)^4+'Scenario Forecasts'!$H$22/(1+$A12)^5)+('Scenario Forecasts'!$H$22*(1+F$7)/($A12-F$7))/(1+$A12)^5-'Inputs & Sources'!$B$18+'Inputs & Sources'!$B$19)/'Inputs & Sources'!$B$20)
A15: Scenario comparison
A16: Case | B16: Year 1 revenue growth | C16: Year 5 EBIT margin | D16: Implied value / share | E16: Current price | F16: Implied upside / (downside) | G16: Board question
A17: Base | B17: ='Scenario Forecasts'!D7 | C17: ='Scenario Forecasts'!H9 | D17: =Valuation!C14 | E17: =Valuation!C15 | F17: =Valuation!C16 | G17: What must be true for the base case?
A18: Upside | B18: ='Scenario Forecasts'!D30 | C18: ='Scenario Forecasts'!H32 | D18: =Valuation!D14 | E18: =Valuation!D15 | F18: =Valuation!D16 | G18: What evidence triggers acceleration?
A19: Downside | B19: ='Scenario Forecasts'!D53 | C19: ='Scenario Forecasts'!H55 | D19: =Valuation!E14 | E19: =Valuation!E15 | F19: =Valuation!E16 | G19: What protects liquidity and option value?

Sheet Board Appendix
A1: BUS311 Capstone Milestone 3 | Board Appendix
A2: Model-linked outputs and visuals designed for the PowerPoint appendix and live-question support during the Oral Presentation.
A3: Legend: blue font / pale yellow = student input | green font = cross-sheet link | black = formula | PASS/REVIEW/INCOMPLETE = control status, not a grade
A5: Scenario valuation and operating evidence
A6: Case | B6: Implied value / share | C6: Current price | D6: Implied upside / (downside) | E6: Enterprise value | F6: Equity value | G6: PV terminal / EV | H6: Year 5 revenue | I6: Year 5 EBIT margin | J6: CFO decision trigger
A7: Base | B7: =IF(Valuation!C14="","",Valuation!C14) | C7: =IF(Valuation!C15="","",Valuation!C15) | D7: =IF(Valuation!C16="","",Valuation!C16) | E7: =IF(Valuation!C9="","",Valuation!C9) | F7: =IF(Valuation!C12="","",Valuation!C12) | G7: =IF(Valuation!C26="","",Valuation!C26) | H7: =IF('Scenario Forecasts'!H8="","",'Scenario Forecasts'!H8) | I7: =IF('Scenario Forecasts'!H9="","",'Scenario Forecasts'!H9)
A8: Upside | B8: =IF(Valuation!D14="","",Valuation!D14) | C8: =IF(Valuation!D15="","",Valuation!D15) | D8: =IF(Valuation!D16="","",Valuation!D16) | E8: =IF(Valuation!D9="","",Valuation!D9) | F8: =IF(Valuation!D12="","",Valuation!D12) | G8: =IF(Valuation!D26="","",Valuation!D26) | H8: =IF('Scenario Forecasts'!H31="","",'Scenario Forecasts'!H31) | I8: =IF('Scenario Forecasts'!H32="","",'Scenario Forecasts'!H32)
A9: Downside | B9: =IF(Valuation!E14="","",Valuation!E14) | C9: =IF(Valuation!E15="","",Valuation!E15) | D9: =IF(Valuation!E16="","",Valuation!E16) | E9: =IF(Valuation!E9="","",Valuation!E9) | F9: =IF(Valuation!E12="","",Valuation!E12) | G9: =IF(Valuation!E26="","",Valuation!E26) | H9: =IF('Scenario Forecasts'!H54="","",'Scenario Forecasts'!H54) | I9: =IF('Scenario Forecasts'!H55="","",'Scenario Forecasts'!H55)
A11: Revenue path by scenario
A12: Fiscal year | B12: Base | C12: Upside | D12: Downside
A13: =IF('Scenario Forecasts'!C6="","",'Scenario Forecasts'!C6) | B13: =IF('Scenario Forecasts'!C8="","",'Scenario Forecasts'!C8) | C13: =IF('Scenario Forecasts'!C31="","",'Scenario Forecasts'!C31) | D13: =IF('Scenario Forecasts'!C54="","",'Scenario Forecasts'!C54)
A14: =IF('Scenario Forecasts'!D6="","",'Scenario Forecasts'!D6) | B14: =IF('Scenario Forecasts'!D8="","",'Scenario Forecasts'!D8) | C14: =IF('Scenario Forecasts'!D31="","",'Scenario Forecasts'!D31) | D14: =IF('Scenario Forecasts'!D54="","",'Scenario Forecasts'!D54)
A15: =IF('Scenario Forecasts'!E6="","",'Scenario Forecasts'!E6) | B15: =IF('Scenario Forecasts'!E8="","",'Scenario Forecasts'!E8) | C15: =IF('Scenario Forecasts'!E31="","",'Scenario Forecasts'!E31) | D15: =IF('Scenario Forecasts'!E54="","",'Scenario Forecasts'!E54)
A16: =IF('Scenario Forecasts'!F6="","",'Scenario Forecasts'!F6) | B16: =IF('Scenario Forecasts'!F8="","",'Scenario Forecasts'!F8) | C16: =IF('Scenario Forecasts'!F31="","",'Scenario Forecasts'!F31) | D16: =IF('Scenario Forecasts'!F54="","",'Scenario Forecasts'!F54)
A17: =IF('Scenario Forecasts'!G6="","",'Scenario Forecasts'!G6) | B17: =IF('Scenario Forecasts'!G8="","",'Scenario Forecasts'!G8) | C17: =IF('Scenario Forecasts'!G31="","",'Scenario Forecasts'!G31) | D17: =IF('Scenario Forecasts'!G54="","",'Scenario Forecasts'!G54)
A18: =IF('Scenario Forecasts'!H6="","",'Scenario Forecasts'!H6) | B18: =IF('Scenario Forecasts'!H8="","",'Scenario Forecasts'!H8) | C18: =IF('Scenario Forecasts'!H31="","",'Scenario Forecasts'!H31) | D18: =IF('Scenario Forecasts'!H54="","",'Scenario Forecasts'!H54)
A21: Implied value per share
A22: Case | B22: Implied value / share | C22: Current price
A23: Base | B23: =IF(B7="","",B7) | C23: =IF(C7="","",C7)
A24: Upside | B24: =IF(B8="","",B8) | C24: =IF(C8="","",C8)
A25: Downside | B25: =IF(B9="","",B9) | C25: =IF(C9="","",C9)
A45: Student Board takeaway and limitations
A46: Primary valuation takeaway
A47: CFO decision implication
A48: Trigger that changes the recommendation
A49: Most important model limitation

Sheet Checks
A1: BUS311 Capstone Milestone 3 | Checks
A2: Visible controls for completeness, signs, cash-flow identities, valuation bridges, scenario order, terminal value, sources, and optional payback.
A3: MODEL STATUS | B3: =IF(COUNTIF(E6:E25,"FAIL")>0,"FAIL",IF(COUNTIF(E6:E25,"INCOMPLETE")>0,"INCOMPLETE",IF(COUNTIF(E6:E25,"REVIEW")>0,"REVIEW","PASS"))) -> INCOMPLETE
A5: Check | B5: Actual | C5: Expected | D5: Difference / tolerance | E5: Status | F5: Where to fix | G5: Why it matters | H5: Student note / limitation
A6: Revenue handoff completeness | B6: =IF('Revenue Handoff'!B6<>"",1,0)+IF('Revenue Handoff'!B7<>"",1,0)+IF('Revenue Handoff'!B8<>"",1,0)+IF('Revenue Handoff'!H19<>"",1,0)+IF('Revenue Handoff'!B12<>"",1,0)+IF('Revenue Handoff'!B13<>"",1,0)+IF('Revenue Handoff'!B14<>"",1,0)+IF('Revenue Handoff'!G12<>"",1,0)+IF('Revenue Handoff'!G13<>"",1,0)+IF('Revenue Handoff'!G14<>"",1,0) -> 0 | C6: 10 | D6: 0 | E6: =IF(B6=0,"INCOMPLETE",IF(B6=C6,"PASS","INCOMPLETE")) -> INCOMPLETE | F6: Revenue Handoff | G6: Revenue hypothesis and scenario logic drive valuation
A7: Core valuation inputs and sources | B7: =COUNT('Inputs & Sources'!B11:B21)+IF('Inputs & Sources'!D11<>"",1,0)+IF('Inputs & Sources'!D12<>"",1,0)+IF('Inputs & Sources'!D13<>"",1,0)+IF('Inputs & Sources'!D14<>"",1,0)+IF('Inputs & Sources'!D15<>"",1,0)+IF('Inputs & Sources'!D16<>"",1,0)+IF('Inputs & Sources'!D17<>"",1,0)+IF('Inputs & Sources'!D18<>"",1,0)+IF('Inputs & Sources'!D19<>"",1,0)+IF('Inputs & Sources'!D20<>"",1,0)+IF('Inputs & Sources'!D21<>"",1,0) -> 0 | C7: 22 | D7: 0 | E7: =IF(B7=0,"INCOMPLETE",IF(B7=C7,"PASS","INCOMPLETE")) -> INCOMPLETE | F7: Inputs & Sources B11:D21 | G7: Required assumptions must be populated and sourced
A8: Scenario assumption completeness | B8: =COUNT('Inputs & Sources'!E36:I40)+COUNT('Inputs & Sources'!J41)+COUNT('Inputs & Sources'!E44:I48)+COUNT('Inputs & Sources'!J49)+COUNT('Inputs & Sources'!E52:I56)+COUNT('Inputs & Sources'!J57) -> 0 | C8: 78 | D8: 0 | E8: =IF(B8=0,"INCOMPLETE",IF(B8=C8,"PASS","INCOMPLETE")) -> INCOMPLETE | F8: Inputs & Sources E36:J57 | G8: All three cases require complete operating assumptions
A9: Capital weights sum | B9: ='Inputs & Sources'!B32 | C9: 1 | D9: 0.01% | E9: =IF(B9="","INCOMPLETE",IF(ABS(B9-C9)<=0.0001,"PASS","FAIL")) -> INCOMPLETE | F9: Inputs & Sources B17:B18 | G9: Market-value weights must total 100%
A10: WACC exceeds base terminal growth | B10: ='Inputs & Sources'!B30-'Inputs & Sources'!J41 -> #VALUE! | C10: 0 | D10: > 0 | E10: =IF(B10="","INCOMPLETE",IF(B10>0,"PASS","FAIL")) -> #VALUE! | F10: Inputs & Sources B30/J41 | G10: Gordon growth requires WACC > g
A11: WACC exceeds upside terminal growth | B11: ='Inputs & Sources'!B30-'Inputs & Sources'!J49 -> #VALUE! | C11: 0 | D11: > 0 | E11: =IF(B11="","INCOMPLETE",IF(B11>0,"PASS","FAIL")) -> #VALUE! | F11: Inputs & Sources B30/J49 | G11: Gordon growth requires WACC > g
A12: WACC exceeds downside terminal growth | B12: ='Inputs & Sources'!B30-'Inputs & Sources'!J57 -> #VALUE! | C12: 0 | D12: > 0 | E12: =IF(B12="","INCOMPLETE",IF(B12>0,"PASS","FAIL")) -> #VALUE! | F12: Inputs & Sources B30/J57 | G12: Gordon growth requires WACC > g
A13: Base FCF identity | B13: =ABS('Scenario Forecasts'!D22-('Scenario Forecasts'!D13+'Scenario Forecasts'!D15-'Scenario Forecasts'!D18-'Scenario Forecasts'!D21))+ABS('Scenario Forecasts'!E22-('Scenario Forecasts'!E13+'Scenario Forecasts'!E15-'Scenario Forecasts'!E18-'Scenario Forecasts'!E21))+ABS('Scenario Forecasts'!F22-('Scenario Forecasts'!F13+'Scenario Forecasts'!F15-'Scenario Forecasts'!F18-'Scenario Forecasts'!F21))+ABS('Scenario Forecasts'!G22-('Scenario Forecasts'!G13+'Scenario Forecasts'!G15-'Scenario Forecasts'!G18-'Scenario Forecasts'!G21))+ABS('Scenario Forecasts'!H22-('Scenario Forecasts'!H13+'Scenario Forecasts'!H15-'Scenario Forecasts'!H18-'Scenario Forecasts'!H21)) -> #VALUE! | C13: 0 | D13: < 0.1 | E13: =IF(COUNT('Scenario Forecasts'!D22:H22)<5,"INCOMPLETE",IF(B13<0.1,"PASS","FAIL")) -> INCOMPLETE | F13: Scenario Forecasts base block | G13: NOPAT + D&A − CapEx − ΔNWC must equal UFCF
A14: Upside FCF identity | B14: =ABS('Scenario Forecasts'!D45-('Scenario Forecasts'!D36+'Scenario Forecasts'!D38-'Scenario Forecasts'!D41-'Scenario Forecasts'!D44))+ABS('Scenario Forecasts'!E45-('Scenario Forecasts'!E36+'Scenario Forecasts'!E38-'Scenario Forecasts'!E41-'Scenario Forecasts'!E44))+ABS('Scenario Forecasts'!F45-('Scenario Forecasts'!F36+'Scenario Forecasts'!F38-'Scenario Forecasts'!F41-'Scenario Forecasts'!F44))+ABS('Scenario Forecasts'!G45-('Scenario Forecasts'!G36+'Scenario Forecasts'!G38-'Scenario Forecasts'!G41-'Scenario Forecasts'!G44))+ABS('Scenario Forecasts'!H45-('Scenario Forecasts'!H36+'Scenario Forecasts'!H38-'Scenario Forecasts'!H41-'Scenario Forecasts'!H44)) -> #VALUE! | C14: 0 | D14: < 0.1 | E14: =IF(COUNT('Scenario Forecasts'!D45:H45)<5,"INCOMPLETE",IF(B14<0.1,"PASS","FAIL")) -> INCOMPLETE | F14: Scenario Forecasts upside block | G14: Scenario cash-flow identity
A15: Downside FCF identity | B15: =ABS('Scenario Forecasts'!D68-('Scenario Forecasts'!D59+'Scenario Forecasts'!D61-'Scenario Forecasts'!D64-'Scenario Forecasts'!D67))+ABS('Scenario Forecasts'!E68-('Scenario Forecasts'!E59+'Scenario Forecasts'!E61-'Scenario Forecasts'!E64-'Scenario Forecasts'!E67))+ABS('Scenario Forecasts'!F68-('Scenario Forecasts'!F59+'Scenario Forecasts'!F61-'Scenario Forecasts'!F64-'Scenario Forecasts'!F67))+ABS('Scenario Forecasts'!G68-('Scenario Forecasts'!G59+'Scenario Forecasts'!G61-'Scenario Forecasts'!G64-'Scenario Forecasts'!G67))+ABS('Scenario Forecasts'!H68-('Scenario Forecasts'!H59+'Scenario Forecasts'!H61-'Scenario Forecasts'!H64-'Scenario Forecasts'!H67)) -> #VALUE! | C15: 0 | D15: < 0.1 | E15: =IF(COUNT('Scenario Forecasts'!D68:H68)<5,"INCOMPLETE",IF(B15<0.1,"PASS","FAIL")) -> INCOMPLETE | F15: Scenario Forecasts downside block | G15: Scenario cash-flow identity
A16: Base enterprise-value tie | B16: =Valuation!C9-SUM(Valuation!C7:C8) -> #VALUE! | C16: 0 | D16: < 0.1 | E16: =IF(Valuation!C9="","INCOMPLETE",IF(ABS(B16)<0.1,"PASS","FAIL")) -> INCOMPLETE | F16: Valuation C7:C9 | G16: EV must equal PV forecast FCF + PV terminal value
A17: Base equity bridge tie | B17: =Valuation!C12-(Valuation!C9-Valuation!C10+Valuation!C11) -> #VALUE! | C17: 0 | D17: < 0.1 | E17: =IF(Valuation!C12="","INCOMPLETE",IF(ABS(B17)<0.1,"PASS","FAIL")) -> INCOMPLETE | F17: Valuation C9:C12 | G17: Equity value must reconcile from enterprise value
A18: Sensitivity center ties to base | B18: =Sensitivities!D10-Valuation!C14 -> #VALUE! | C18: 0 | D18: < 0.01 | E18: =IF(Sensitivities!D10="","INCOMPLETE",IF(ABS(B18)<0.01,"PASS","FAIL")) -> INCOMPLETE | F18: Sensitivities D10 | G18: The sensitivity table must use the live base valuation
A19: Scenario ordering | B19: =IF(AND(Valuation!E14<=Valuation!C14,Valuation!C14<=Valuation!D14),0,1) -> 0 | C19: 0 | D19: 0 | E19: =IF(COUNT(Valuation!C14:E14)<3,"INCOMPLETE",IF(B19=0,"PASS","REVIEW")) -> INCOMPLETE | F19: Inputs & Sources scenario assumptions | G19: Upside/base/downside should reflect the named driver unless explained
A20: Base terminal-value share | B20: =Valuation!C26 | C20: 0.4 | D20: 40%–85% | E20: =IF(B20="","INCOMPLETE",IF(AND(B20>=0.4,B20<=0.85),"PASS","REVIEW")) -> INCOMPLETE | F20: Valuation C26 | G20: High or low terminal dependence requires judgment
A21: Base implied terminal multiple | B21: =Valuation!C27 | C21: 25 | D21: 0x–25x | E21: =IF(B21="","INCOMPLETE",IF(AND(B21>0,B21<=25),"PASS","REVIEW")) -> INCOMPLETE | F21: Valuation C27 | G21: Compare implied steady-state economics with reality
A22: Sensitivity direction | B22: =IF(AND(Sensitivities!D11<Sensitivities!D10,Sensitivities!E10>Sensitivities!D10),0,1) -> 1 | C22: 0 | D22: 0 | E22: =IF(Sensitivities!D10="","INCOMPLETE",IF(B22=0,"PASS","FAIL")) -> INCOMPLETE | F22: Sensitivities | G22: Higher WACC lowers value; higher g raises value
A23: Optional project model completeness | B23: =IF('Decision Economics'!B7="No",1,COUNT('Decision Economics'!B9:B13)+COUNT('Decision Economics'!D19:H20)) -> 1 | C23: 1 | D23: No: 1; Yes: 15 | E23: =IF('Decision Economics'!B7="No","PASS",IF(B23=15,"PASS","INCOMPLETE")) -> PASS | F23: Decision Economics | G23: Optional analysis must be complete when used
A24: Optional project FCF sign / sources-uses | B24: =IF('Decision Economics'!B7="No",0,'Decision Economics'!C32-(-'Decision Economics'!C26-'Decision Economics'!C27)) -> 0 | C24: 0 | D24: < 0.1 | E24: =IF('Decision Economics'!B7="No","PASS",IF(ABS(B24)<0.1,"PASS","FAIL")) -> PASS | F24: Decision Economics C26:C32 | G24: Initial CapEx and NWC are cash uses
A25: Optional project payback behavior | B25: =IF('Decision Economics'!B7="No",1,IF(OR('Decision Economics'!B40="No payback",AND(ISNUMBER('Decision Economics'!B40),'Decision Economics'!B40>=0,'Decision Economics'!B40<=5)),1,0)) -> 1 | C25: 1 | D25: 1 | E25: =IF(B25=1,"PASS","FAIL") -> PASS | F25: Decision Economics B40 | G25: Payback must be fractional/guarded and never return a formula error
A27: Blank-state standard: a new student file should show INCOMPLETE and blank decision outputs, never Excel error codes or misleading zero valuations.

Sheet Sources
A1: BUS311 Capstone Milestone 3 | Sources
A2: Source log for every material reported fact and forecast assumption; use stable links or exact filing/report locations.
A3: Legend: blue font / pale yellow = student input | green font = cross-sheet link | black = formula | PASS/REVIEW/INCOMPLETE = control status, not a grade
A5: Source ID | B5: Assumption / metric supported | C5: Source type | D5: Organization / document / FactSet report | E5: Period / as-of | F5: Units / currency | G5: Definition / adjustments | H5: Exact page, table, screen, or stable URL | I5: Accessed date | J5: Limitation / comparability
A6: S01
A7: S02
A8: S03
A9: S04
A10: S05
A11: S06
A12: S07
A13: S08
A14: S09
A15: S10
A16: S11
A17: S12
... A45: S40
