Workbook

Sheet Exercise - Student
A1: Corporate Finance Valuation Exercise
A3: Instructions
A4: 1) Review the given input assumptions (green cells)
A5: 2) Compute Cost of Equity, after-tax Cost of Debt, and WACC
A6: 3) Complete Net Operating Profit After Tax (NOPAT), ∆NWC, and Free Cash Flow
A7: 4) Compute Horizon (Terminal) Value using Gordon Growth Formula
A8: 5) Discount to present value at WACC and sum to Enterprise Value( EV)
A9: 6) Compute Equity Value and Equity Value per Share
A11: Assumptions (Inputs) | B11: Value - $ millions & % | E11: WACC Calculation (To-Do) | F11: Your calc | G11: Check
A12: Risk-free rate (Rf) | B12: 0.03 | E12: Cost of Equity (CAPM) | G12: =IF(ISNUMBER(F12),IF(ABS(F12-Solution!F12)<=0.0001,"✅","❌"),"⌛") -> ⌛
A13: Market risk premium (MRP) | B13: 0.05 | E13: After-tax Cost of Debt | G13: =IF(ISNUMBER(F13),IF(ABS(F13-Solution!F13)<=0.0001,"✅","❌"),"⌛") -> ⌛
A14: Beta | B14: 1.2 | E14: WACC | G14: =IF(ISNUMBER(F14),IF(ABS(F14-Solution!F14)<=0.0001,"✅","❌"),"⌛") -> ⌛
A15: Cost of debt (pre-tax) | B15: 0.06
A16: Tax rate | B16: 0.25
A17: Target equity weight (We) | B17: 0.7
A18: Target debt weight (Wd) | B18: 0.3
A19: Long-term growth (g) | B19: 0.025
A20: Base revenue (Year 0) | B20: 120
A21: EBITDA margin % | B21: 0.18
A22: D&A % of sales | B22: 0.05
A23: Capex % of sales | B23: 0.06 | I23: Note: Capex % (6%) > D&A % (5%) — this company is a net capital consumer. Discussion: What does this imply about the relationship between investment and growth?
A24: NWC % of sales | B24: 0.1
A25: NWC | B25: =$B$24*$B$20 -> 12
A26: Net debt (= Total Debt − Cash) | B26: 50
A27: Shares outstanding (m) | B27: 10
A30: Projection Drivers & FCF (To-Do highlighted)
A31: Metric | B31: Year 1 | C31: Year 2 | D31: Year 3 | E31: Year 4 | F31: Year 5
A32: Revenue growth % | B32: 0.08 | C32: 0.07 | D32: 0.06 | E32: 0.05 | F32: 0.04 | I32: Growth rates taper from 8% → 4% as the company matures. The terminal growth rate (g = 2.5%) approximates long-run nominal GDP growth — a company cannot grow faster than the economy forever.
A33: Revenue | B33: =$B$20*(1+B32) -> 129.6 | C33: =B33*(1+C32) -> 138.672 | D33: =C33*(1+D32) -> 146.99232 | E33: =D33*(1+E32) -> 154.34194 | F33: =E33*(1+F32) -> 160.51561
A34: EBITDA margin % | B34: =$B$21 -> 0.18 | C34: =$B$21 -> 0.18 | D34: =$B$21 -> 0.18 | E34: =$B$21 -> 0.18 | F34: =$B$21 -> 0.18
A35: EBITDA | B35: =B33*B34 -> 23.328 | C35: =C33*C34 -> 24.96096 | D35: =D33*D34 -> 26.458618 | E35: =E33*E34 -> 27.781548 | F35: =F33*F34 -> 28.89281
A36: D&A % of sales | B36: =$B$22 -> 0.05 | C36: =$B$22 -> 0.05 | D36: =$B$22 -> 0.05 | E36: =$B$22 -> 0.05 | F36: =$B$22 -> 0.05
A37: D&A | B37: =B33*B36 -> 6.48 | C37: =C33*C36 -> 6.9336 | D37: =D33*D36 -> 7.349616 | E37: =E33*E36 -> 7.7170968 | F37: =F33*F36 -> 8.0257807 | I37: D&A is a non-cash accounting expense — it reduces EBIT (and therefore taxes paid) but involves no cash outflow. We subtract it here to get EBIT, then add it back in the FCF calculation.
A38: EBIT | B38: =B35-B37 -> 16.848 | C38: =C35-C37 -> 18.02736 | D38: =D35-D37 -> 19.109002 | E38: =E35-E37 -> 20.064452 | F38: =F35-F37 -> 20.86703
A39: Tax rate | B39: =$B$16 -> 0.25 | C39: =$B$16 -> 0.25 | D39: =$B$16 -> 0.25 | E39: =$B$16 -> 0.25 | F39: =$B$16 -> 0.25
A40: Net Operating Profit After Taxes | I40: NOPAT = EBIT × (1 − Tax Rate) [Operating profit after tax, excluding the effect of financing]
A41: Check: NOPAT | B41: =IF(ISNUMBER(B40),IF(ABS(B40-Solution!B40)<=0.01,"✅","❌"),"⌛") -> ⌛ | C41: =IF(ISNUMBER(C40),IF(ABS(C40-Solution!C40)<=0.01,"✅","❌"),"⌛") -> ⌛ | D41: =IF(ISNUMBER(D40),IF(ABS(D40-Solution!D40)<=0.01,"✅","❌"),"⌛") -> ⌛ | E41: =IF(ISNUMBER(E40),IF(ABS(E40-Solution!E40)<=0.01,"✅","❌"),"⌛") -> ⌛ | F41: =IF(ISNUMBER(F40),IF(ABS(F40-Solution!F40)<=0.01,"✅","❌"),"⌛") -> ⌛
A42: Capex % of sales | B42: =$B$23 -> 0.06 | C42: =$B$23 -> 0.06 | D42: =$B$23 -> 0.06 | E42: =$B$23 -> 0.06 | F42: =$B$23 -> 0.06
A43: Capex | B43: =B33*B42 -> 7.776 | C43: =C33*C42 -> 8.32032 | D43: =D33*D42 -> 8.8195392 | E43: =E33*E42 -> 9.2605162 | F43: =F33*F42 -> 9.6309368
A44: NWC % of sales | B44: =$B$24 -> 0.1 | C44: =$B$24 -> 0.1 | D44: =$B$24 -> 0.1 | E44: =$B$24 -> 0.1 | F44: =$B$24 -> 0.1
...

Sheet Exercise-Completed
A1: Corporate Finance Valuation Exercise
A3: Instructions
A4: 1) Review the given input assumptions (green cells)
A5: 2) Compute Cost of Equity, after-tax Cost of Debt, and WACC
A6: 3) Complete Net Operating Profit After Tax (NOPAT), ∆NWC, and Free Cash Flow
A7: 4) Compute Horizon (Terminal) Value using Gordon Growth Formula
A8: 5) Discount to present value at WACC and sum to Enterprise Value( EV)
A9: 6) Compute Equity Value and Equity Value per Share
A11: Assumptions (Inputs) | B11: Value - $ millions & % | E11: WACC Calculation (To-Do) | F11: Your calc | G11: Check
A12: Risk-free rate (Rf) | B12: 0.03 | E12: Cost of Equity (CAPM) | F12: =B12+B14*(B13) -> 0.09 | G12: =IF(ISNUMBER(F12),IF(ABS(F12-Solution!F12)<=0.0001,"✅","❌"),"⌛") -> ✅
A13: Market risk premium (MRP) | B13: 0.05 | E13: After-tax Cost of Debt | F13: =B15*(1-B16) -> 0.045 | G13: =IF(ISNUMBER(F13),IF(ABS(F13-Solution!F13)<=0.0001,"✅","❌"),"⌛") -> ✅
A14: Beta | B14: 1.2 | E14: WACC | F14: =B17*F12+B18*F13 -> 0.0765 | G14: =IF(ISNUMBER(F14),IF(ABS(F14-Solution!F14)<=0.0001,"✅","❌"),"⌛") -> ✅
A15: Cost of debt (pre-tax) | B15: 0.06
A16: Tax rate | B16: 0.25
A17: Target equity weight (We) | B17: 0.7
A18: Target debt weight (Wd) | B18: 0.3
A19: Long-term growth (g) | B19: 0.025
A20: Base revenue (Year 0) | B20: 120
A21: EBITDA margin % | B21: 0.18
A22: D&A % of sales | B22: 0.05
A23: Capex % of sales | B23: 0.06 | I23: Note: Capex % (6%) > D&A % (5%) — this company is a net capital consumer. Discussion: What does this imply about the relationship between investment and growth?
A24: NWC % of sales | B24: 0.1
A25: NWC | B25: =$B$24*$B$20 -> 12 | C25: =_xlfn.FORMULATEXT(B25) -> =$B$24*$B$20
A26: Net debt (= Total Debt − Cash) | B26: 50
A27: Shares outstanding (m) | B27: 10
A30: Projection Drivers & FCF (To-Do highlighted)
A31: Metric | B31: Year 1 | C31: Year 2 | D31: Year 3 | E31: Year 4 | F31: Year 5
A32: Revenue growth % | B32: 0.08 | C32: 0.07 | D32: 0.06 | E32: 0.05 | F32: 0.04 | I32: Growth rates taper from 8% → 4% as the company matures. The terminal growth rate (g = 2.5%) approximates long-run nominal GDP growth — a company cannot grow faster than the economy forever.
A33: Revenue | B33: =$B$20*(1+B32) -> 129.6 | C33: =B33*(1+C32) -> 138.672 | D33: =C33*(1+D32) -> 146.99232 | E33: =D33*(1+E32) -> 154.34194 | F33: =E33*(1+F32) -> 160.51561
A34: EBITDA margin % | B34: =$B$21 -> 0.18 | C34: =$B$21 -> 0.18 | D34: =$B$21 -> 0.18 | E34: =$B$21 -> 0.18 | F34: =$B$21 -> 0.18
A35: EBITDA | B35: =B33*B34 -> 23.328 | C35: =C33*C34 -> 24.96096 | D35: =D33*D34 -> 26.458618 | E35: =E33*E34 -> 27.781548 | F35: =F33*F34 -> 28.89281
A36: D&A % of sales | B36: =$B$22 -> 0.05 | C36: =$B$22 -> 0.05 | D36: =$B$22 -> 0.05 | E36: =$B$22 -> 0.05 | F36: =$B$22 -> 0.05
A37: D&A | B37: =B33*B36 -> 6.48 | C37: =C33*C36 -> 6.9336 | D37: =D33*D36 -> 7.349616 | E37: =E33*E36 -> 7.7170968 | F37: =F33*F36 -> 8.0257807 | I37: D&A is a non-cash accounting expense — it reduces EBIT (and therefore taxes paid) but involves no cash outflow. We subtract it here to get EBIT, then add it back in the FCF calculation.
A38: EBIT | B38: =B35-B37 -> 16.848 | C38: =C35-C37 -> 18.02736 | D38: =D35-D37 -> 19.109002 | E38: =E35-E37 -> 20.064452 | F38: =F35-F37 -> 20.86703
A39: Tax rate | B39: =$B$16 -> 0.25 | C39: =$B$16 -> 0.25 | D39: =$B$16 -> 0.25 | E39: =$B$16 -> 0.25 | F39: =$B$16 -> 0.25
A40: Net Operating Profit After Taxes | B40: =B38-(B38*B39) -> 12.636 | C40: =C38-(C38*C39) -> 13.52052 | D40: =D38-(D38*D39) -> 14.331751 | E40: =E38-(E38*E39) -> 15.048339 | F40: =F38-(F38*F39) -> 15.650272 | I40: NOPAT = EBIT × (1 − Tax Rate) [Operating profit after tax, excluding the effect of financing]
A41: Check: NOPAT | B41: =IF(ISNUMBER(B40),IF(ABS(B40-Solution!B40)<=0.01,"✅","❌"),"⌛") -> ✅ | C41: =IF(ISNUMBER(C40),IF(ABS(C40-Solution!C40)<=0.01,"✅","❌"),"⌛") -> ✅ | D41: =IF(ISNUMBER(D40),IF(ABS(D40-Solution!D40)<=0.01,"✅","❌"),"⌛") -> ✅ | E41: =IF(ISNUMBER(E40),IF(ABS(E40-Solution!E40)<=0.01,"✅","❌"),"⌛") -> ✅ | F41: =IF(ISNUMBER(F40),IF(ABS(F40-Solution!F40)<=0.01,"✅","❌"),"⌛") -> ✅
A42: Capex % of sales | B42: =$B$23 -> 0.06 | C42: =$B$23 -> 0.06 | D42: =$B$23 -> 0.06 | E42: =$B$23 -> 0.06 | F42: =$B$23 -> 0.06
A43: Capex | B43: =B33*B42 -> 7.776 | C43: =C33*C42 -> 8.32032 | D43: =D33*D42 -> 8.8195392 | E43: =E33*E42 -> 9.2605162 | F43: =F33*F42 -> 9.6309368
A44: NWC % of sales | B44: =$B$24 -> 0.1 | C44: =$B$24 -> 0.1 | D44: =$B$24 -> 0.1 | E44: =$B$24 -> 0.1 | F44: =$B$24 -> 0.1
...

Sheet Solution
A1: Solution (Hidden) – Auto-check calculations
F12: ='Exercise-Completed'!B12+'Exercise-Completed'!B14*'Exercise-Completed'!B13 -> 0.09
F13: ='Exercise-Completed'!B15*(1-'Exercise-Completed'!B16) -> 0.045
F14: ='Exercise-Completed'!B17*F12+'Exercise-Completed'!B18*F13 -> 0.0765
B40: ='Exercise-Completed'!B38*(1-'Exercise-Completed'!B39) -> 12.636 | C40: ='Exercise-Completed'!C38*(1-'Exercise-Completed'!C39) -> 13.52052 | D40: ='Exercise-Completed'!D38*(1-'Exercise-Completed'!D39) -> 14.331751 | E40: ='Exercise-Completed'!E38*(1-'Exercise-Completed'!E39) -> 15.048339 | F40: ='Exercise-Completed'!F38*(1-'Exercise-Completed'!F39) -> 15.650272
B46: ='Exercise-Completed'!B45-'Exercise-Completed'!B25 -> 0.96 | C46: ='Exercise-Completed'!C45-'Exercise-Completed'!B45 -> 0.9072 | D46: ='Exercise-Completed'!D45-'Exercise-Completed'!C45 -> 0.832032 | E46: ='Exercise-Completed'!E45-'Exercise-Completed'!D45 -> 0.7349616 | F46: ='Exercise-Completed'!F45-'Exercise-Completed'!E45 -> 0.61736774
B48: =B40+'Exercise-Completed'!B37-'Exercise-Completed'!B43-B46 -> 10.38 | C48: =C40+'Exercise-Completed'!C37-'Exercise-Completed'!C43-C46 -> 11.2266 | D48: =D40+'Exercise-Completed'!D37-'Exercise-Completed'!D43-D46 -> 12.029796 | E48: =E40+'Exercise-Completed'!E37-'Exercise-Completed'!E43-E46 -> 12.769958 | F48: =F40+'Exercise-Completed'!F37-'Exercise-Completed'!F43-F46 -> 13.427748
B52: =B48/(1+F14)^1 -> 9.6423595 | C52: =C48/(1+F14)^2 -> 9.6876888 | D52: =D48/(1+F14)^3 -> 9.6430887 | E52: =E48/(1+F14)^4 -> 9.5089667 | F52: =F48/(1+F14)^5 -> 9.2882314
F54: =F48*(1+'Exercise-Completed'!B19)/(F14-'Exercise-Completed'!B19) -> 267.2513
F55: =F54/(1+F14)^5 -> 184.86286
B56: =SUM(B52:F52)+F55 -> 232.63319
B57: =B56-'Exercise-Completed'!B26 -> 182.63319
B58: =B57/'Exercise-Completed'!B27 -> 18.263319
